Workbook

Sheet GERAL
B1: SEM MIP | C1: ninst | D1: tem_janelas | E1: heuristica_retirada | F1: tamanho_clientes | G1: nos_rede | H1: veiculos | I1: capacidade | J1: tabu | K1: tipo_geracao | L1: tempo_exato | M1: tempo_bp | N1: fo_exato | O1: fo_bp | P1: gap_pct | Q1: igual_exato | R1: nos_bp | S1: colunas_bp | T1: seq_exato | V1: seq_bp | Y1: LITERATURA | AI1: 10 X LITERATURA Sem Mip
A2: run_id | B2: arquivo_instancia | C2: ninst | D2: tem_janelas | E2: heuristica_retirada | F2: tamanho_clientes | G2: nos_rede | H2: veiculos | I2: capacidade | J2: tabu | K2: tipo_geracao | L2: tempo_exato | M2: tempo_bp | N2: fo_exato | O2: fo_bp | P2: gap_pct | Q2: igual_exato | R2: nos_bp | S2: colunas_bp | T2: seq_exato | V2: seq_bp | W2: timestamp | Y2: Problema | Z2: Nodes | AA2: Arcs | AB2: LP | AC2: IP | AD2: Vehicles | AE2: BB_Nodes | AF2: Columns | AG2: CPU | AI2: Problema | AJ2: Nodes | AK2: Arcs | AL2: LP | AM2: IP | AN2: Vehicles | AO2: BB_Nodes | AP2: Columns | AQ2: CPU
A3: tam25_cap200_tabu0_inst0_cons10 | B3: instancias/c101N.txt | C3: 0 | D3: 0 | E3: 10 | F3: 25 | G3: 27 | H3: 3 | I3: 200 | J3: 0 | K3: PD | L3: 0.2661 | M3: 108.8039 | N3: 191.8136 | O3: 191.8136 | P3: 0 | Q3: 1 | R3: 1 | S3: 975 | T3: V0: [0,13,17,18,19,15,16,14,12,26] ; V1: [0,20,24,25,23,22,21,26] ; V2: [0,5,3,7,8,10,11,9,6,4,2,1,26] | U3: V0: [0,5,3,7,8,10,11,9,6,4,2,1,26] ; V1: [0,20,24,25,23,22,21,26] ; V2: [0,13,17,18,19,15,16,14,12,26] | V3: 46113.822 | Y3: C101 | Z3: 25 | AA3: 332 | AB3: 191.3 | AC3: 191.3 | AD3: 3 | AE3: 1 | AF3: 498 | AG3: 18.6 | AI3: C101 | AJ3: 25 | AL3: 191.3 | AM3: 191.3 | AN3: 3 | AO3: 1 | AP3: =S3/AF3 -> 1.9578313 | AQ3: =M3/AG3 -> 5.849672
A4: tam25_cap200_tabu0_inst0_cons10 | B4: instancias/c102.txt | C4: 0 | D4: 0 | E4: 10 | F4: 25 | G4: 27 | H4: 3 | I4: 200 | J4: 0 | K4: PD | L4: 19.595 | M4: 828.1247 | N4: 190.7376 | O4: 190.7376 | P4: 0 | Q4: 1 | R4: 1 | S4: 2391 | T4: V0: [0,7,8,10,11,9,6,4,2,1,3,5,26] ; V1: [0,20,24,25,23,22,21,26] ; V2: [0,13,17,18,19,15,16,14,12,26] | U4: V0: [0,13,17,18,19,15,16,14,12,26] ; V1: [0,20,24,25,23,22,21,26] ; V2: [0,7,8,10,11,9,6,4,2,1,3,5,26] | V4: 46113.832 | Y4: C102 | Z4: 25 | AA4: 473 | AB4: 190.3 | AC4: 190.3 | AD4: 3 | AE4: 1 | AF4: 534 | AG4: 79.7 | AI4: C102 | AJ4: 25 | AL4: 190.3 | AM4: 190.3 | AN4: 3 | AO4: 1 | AP4: =S4/AF4 -> 4.4775281 | AQ4: =M4/AG4 -> 10.390523 | AX4: GAP
A5: tam25_cap200_tabu0_inst0_cons10 | B5: instancias/c103.txt | C5: 0 | D5: 0 | E5: 10 | F5: 25 | G5: 27 | H5: 3 | I5: 200 | J5: 0 | K5: PD | L5: 1201.4904 | M5: 1009.9421 | N5: 190.7376 | O5: 190.7376 | P5: 0 | Q5: 1 | R5: 1 | S5: 2328 | T5: V0: [0,20,24,25,23,22,21,26] ; V1: [0,13,17,18,19,15,16,14,12,26] ; V2: [0,7,8,10,11,9,6,4,2,1,3,5,26] | U5: V0: [0,7,8,10,11,9,6,4,2,1,3,5,26] ; V1: [0,20,24,25,23,22,21,26] ; V2: [0,13,17,18,19,15,16,14,12,26] | V5: 46113.857 | Y5: C103 | Z5: 25 | AA5: 569 | AB5: 190.3 | AC5: 190.3 | AD5: 3 | AE5: 1 | AF5: 447 | AG5: 134.7 | AI5: C103 | AJ5: 25 | AL5: 190.3 | AM5: 190.3 | AN5: 3 | AO5: 1 | AP5: =S5/AF5 -> 5.2080537 | AQ5: =M5/AG5 -> 7.4977142 | AW5: heuristica | AX5: MÁXIMO | AY5: inst | AZ5: MÍNIMO | BA5: inst | BB5: MÉDIA
A6: tam25_cap200_tabu0_inst0_cons10 | B6: instancias/c104.txt | C6: 0 | D6: 0 | E6: 10 | F6: 25 | G6: 27 | H6: 3 | I6: 200 | J6: 0 | K6: PD | L6: 1201.9546 | M6: 518.4715 | N6: 187.4495 | O6: 190.7412 | P6: 1.7561 | Q6: 0 | R6: 1 | S6: 2121 | T6: V0: [0,7,8,11,9,6,4,2,1,3,5,26] ; V1: [0,20,24,25,23,22,21,26] ; V2: [0,13,17,18,19,15,16,14,12,10,26] | U6: V0: [0,20,24,25,23,22,21,26] ; V1: [0,13,15,12,14,16,19,18,17,10,26] ; V2: [0,7,8,11,9,6,4,2,1,3,5,26] | V6: 46113.877 | Y6: C104 | Z6: 25 | AA6: 604 | AB6: 186.9 | AC6: 186.9 | AD6: 3 | AE6: 1 | AF6: 485 | AG6: 223.9 | AI6: C104 | AJ6: 25 | AL6: 186.9 | AM6: 186.9 | AN6: 3 | AO6: 1 | AP6: =S6/AF6 -> 4.3731959 | AQ6: =M6/AG6 -> 2.3156387 | AW6: 0 | AX6: =IFERROR(_xlfn.MAXIFS('resultados_finais - Copia (4)'!$P:$P,'resultados_finais - Copia (4)'!$E:$E,AW6,'resultados_finais - Copia (4)'!$P:$P,">=0"),"") -> 9.7493 | AY6: instancias/c202,txt | AZ6: =IFERROR(_xlfn.MINIFS('resultados_finais - Copia (4)'!$P:$P,'resultados_finais - Copia (4)'!$E:$E,AW6,'resultados_finais - Copia (4)'!$P:$P,">=0"),"") -> 0 | BA6: instancias/r101,txt | BB6: =IFERROR(AVERAGEIFS($O:$O,$E:$E,AW6,$O:$O,">=0"),"")
A7: tam25_cap200_tabu0_inst0_cons10 | B7: instancias/c105.txt | C7: 0 | D7: 0 | E7: 10 | F7: 25 | G7: 27 | H7: 3 | I7: 200 | J7: 0 | K7: PD | L7: 0.6184 | M7: 684.6371 | N7: 191.8136 | O7: 191.8136 | P7: 0 | Q7: 1 | R7: 1 | S7: 2424 | T7: V0: [0,13,17,18,19,15,16,14,12,26] ; V1: [0,5,3,7,8,10,11,9,6,4,2,1,26] ; V2: [0,20,24,25,23,22,21,26] | U7: V0: [0,5,3,7,8,10,11,9,6,4,2,1,26] ; V1: [0,13,17,18,19,15,16,14,12,26] ; V2: [0,20,24,25,23,22,21,26] | V7: 46113.885 | Y7: C105 | Z7: 25 | AA7: 357 | AB7: 191.3 | AC7: 191.3 | AD7: 3 | AE7: 1 | AF7: 531 | AG7: 25.6 | AI7: C105 | AJ7: 25 | AL7: 191.3 | AM7: 191.3 | AN7: 3 | AO7: 1 | AP7: =S7/AF7 -> 4.5649718 | AQ7: =M7/AG7 -> 26.743637 | AV7: inserção com melhoria | AW7: 1 | AX7: =IFERROR(_xlfn.MAXIFS('resultados_finais - Copia (4)'!$P:$P,'resultados_finais - Copia (4)'!$E:$E,AW7,'resultados_finais - Copia (4)'!$P:$P,">=0"),"") -> 17.725 | AY7: instancias/c202,txt | AZ7: =IFERROR(_xlfn.MINIFS('resultados_finais - Copia (4)'!$P:$P,'resultados_finais - Copia (4)'!$E:$E,AW7,'resultados_finais - Copia (4)'!$P:$P,">=0"),"") -> 0 | BA7: instancias/r101,txt | BB7: =IFERROR(AVERAGEIFS($O:$O,$E:$E,AW7,$O:$O,">=0"),"")
A8: tam25_cap200_tabu0_inst0_cons10 | B8: instancias/c106.txt | C8: 0 | D8: 0 | E8: 10 | F8: 25 | G8: 27 | H8: 3 | I8: 200 | J8: 0 | K8: PD | L8: 0.3072 | M8: 418.1565 | N8: 191.8136 | O8: 191.8136 | P8: 0 | Q8: 1 | R8: 1 | S8: 1686 | T8: V0: [0,20,24,25,23,22,21,26] ; V1: [0,5,3,7,8,10,11,9,6,4,2,1,26] ; V2: [0,13,17,18,19,15,16,14,12,26] | U8: V0: [0,13,17,18,19,15,16,14,12,26] ; V1: [0,20,24,25,23,22,21,26] ; V2: [0,5,3,7,8,10,11,9,6,4,2,1,26] | V8: 46113.89 | Y8: C106 | Z8: 25 | AA8: 336 | AB8: 191.3 | AC8: 191.3 | AD8: 3 | AE8: 1 | AF8: 447 | AG8: 20.7 | AI8: C106 | AJ8: 25 | AL8: 191.3 | AM8: 191.3 | AN8: 3 | AO8: 1 | AP8: =S8/AF8 -> 3.7718121 | AQ8: =M8/AG8 -> 20.200797 | AV8: vns_ com acrescimo | AW8: 2 | AX8: =IFERROR(_xlfn.MAXIFS('resultados_finais - Copia (4)'!$P:$P,'resultados_finais - Copia (4)'!$E:$E,AW8,'resultados_finais - Copia (4)'!$P:$P,">=0"),"") -> 4.95 | AY8: instancias/c202,txt | AZ8: =IFERROR(_xlfn.MINIFS('resultados_finais - Copia (4)'!$P:$P,'resultados_finais - Copia (4)'!$E:$E,AW8,'resultados_finais - Copia (4)'!$P:$P,">=0"),"") -> 0 | BA8: instancias/r101,txt | BB8: =IFERROR(AVERAGEIFS($O:$O,$E:$E,AW8,$O:$O,">=0"),"")
A9: tam25_cap200_tabu0_inst0_cons10 | B9: instancias/c107.txt | C9: 0 | D9: 0 | E9: 10 | F9: 25 | G9: 27 | H9: 3 | I9: 200 | J9: 0 | K9: PD | L9: 0.6161 | M9: 340.2205 | N9: 191.8136 | O9: 191.8136 | P9: 0 | Q9: 1 | R9: 1 | S9: 2040 | T9: V0: [0,5,3,7,8,10,11,9,6,4,2,1,26] ; V1: [0,13,17,18,19,15,16,14,12,26] ; V2: [0,20,24,25,23,22,21,26] | U9: V0: [0,13,17,18,19,15,16,14,12,26] ; V1: [0,20,24,25,23,22,21,26] ; V2: [0,5,3,7,8,10,11,9,6,4,2,1,26] | V9: 46113.894 | Y9: C107 | Z9: 25 | AA9: 377 | AB9: 191.3 | AC9: 191.3 | AD9: 3 | AE9: 1 | AF9: 514 | AG9: 31.7 | AI9: C107 | AJ9: 25 | AL9: 191.3 | AM9: 191.3 | AN9: 3 | AO9: 1 | AP9: =S9/AF9 -> 3.9688716 | AQ9: =M9/AG9 -> 10.732508 | AV9: sem pd | AW9: 3 | AX9: =IFERROR(_xlfn.MAXIFS('resultados_finais - Copia (4)'!$P:$P,'resultados_finais - Copia (4)'!$E:$E,AW9,'resultados_finais - Copia (4)'!$P:$P,">=0"),"") -> 8.4445 | AY9: instancias/c201,txt | AZ9: =IFERROR(_xlfn.MINIFS('resultados_finais - Copia (4)'!$P:$P,'resultados_finais - Copia (4)'!$E:$E,AW9,'resultados_finais - Copia (4)'!$P:$P,">=0"),"") -> 0 | BA9: instancias/r101,txt | BB9: =IFERROR(AVERAGEIFS($O:$O,$E:$E,AW9,$O:$O,">=0"),"")
A10: tam25_cap200_tabu0_inst0_cons10 | B10: instancias/c108.txt | C10: 0 | D10: 0 | E10: 10 | F10: 25 | G10: 27 | H10: 3 | I10: 200 | J10: 0 | K10: PD | L10: 15.0551 | M10: 683.342 | N10: 191.8136 | O10: 191.8136 | P10: 0 | Q10: 1 | R10: 1 | S10: 2415 | T10: V0: [0,20,24,25,23,22,21,26] ; V1: [0,13,17,18,19,15,16,14,12,26] ; V2: [0,5,3,7,8,10,11,9,6,4,2,1,26] | U10: V0: [0,13,17,18,19,15,16,14,12,26] ; V1: [0,20,24,25,23,22,21,26] ; V2: [0,5,3,7,8,10,11,9,6,4,2,1,26] | V10: 46113.902 | Y10: C108 | Z10: 25 | AA10: 431 | AB10: 191.3 | AC10: 191.3 | AD10: 3 | AE10: 1 | AF10: 513 | AG10: 43.1 | AI10: C108 | AJ10: 25 | AL10: 191.3 | AM10: 191.3 | AN10: 3 | AO10: 1 | AP10: =S10/AF10 -> 4.7076023 | AQ10: =M10/AG10 -> 15.854803 | AU10: construtivas | AV10: apenas pd | AW10: 22 | AX10: =IFERROR(_xlfn.MAXIFS('resultados_finais - Copia (4)'!$P:$P,'resultados_finais - Copia (4)'!$E:$E,AW10,'resultados_finais - Copia (4)'!$P:$P,">=0"),"") -> 25.9309 | AY10: instancias/r102,txt | AZ10: =IFERROR(_xlfn.MINIFS('resultados_finais - Copia (4)'!$P:$P,'resultados_finais - Copia (4)'!$E:$E,AW10,'resultados_finais - Copia (4)'!$P:$P,">=0"),"") -> 0 | BA10: instancias/r101,txt | BB10: =IFERROR(AVERAGEIFS($O:$O,$E:$E,AW10,$O:$O,">=0"),"")
A11: tam25_cap200_tabu0_inst0_cons10 | B11: instancias/c109.txt | C11: 0 | D11: 0 | E11: 10 | F11: 25 | G11: 27 | H11: 3 | I11: 200 | J11: 0 | K11: PD | L11: 1200.9615 | M11: 905.8647 | N11: 191.8136 | O11: 191.8136 | P11: 0 | Q11: 1 | R11: 1 | S11: 2028 | T11: V0: [0,5,3,7,8,10,11,9,6,4,2,1,26] ; V1: [0,20,24,25,23,22,21,26] ; V2: [0,13,17,18,19,15,16,14,12,26] | U11: V0: [0,13,17,18,19,15,16,14,12,26] ; V1: [0,5,3,7,8,10,11,9,6,4,2,1,26] ; V2: [0,20,24,25,23,22,21,26] | V11: 46113.926 | Y11: C109 | Z11: 25 | AA11: 482 | AB11: 189.4 | AC11: 191.3 | AD11: 3 | AE11: 3 | AF11: 1747 | AG11: 585.4 | AI11: C109 | AJ11: 25 | AL11: 189.4 | AM11: 191.3 | AN11: 3 | AO11: 3 | AP11: =S11/AF11 -> 1.1608472 | AQ11: =M11/AG11 -> 1.5474286 | AV11: todas | AW11: 10 | AX11: =IFERROR(_xlfn.MAXIFS('resultados_finais - Copia (4)'!$P:$P,'resultados_finais - Copia (4)'!$E:$E,AW11,'resultados_finais - Copia (4)'!$P:$P,">=0"),"") -> 3.3816 | AY11: instancias/c109,txt | AZ11: =IFERROR(_xlfn.MINIFS('resultados_finais - Copia (4)'!$P:$P,'resultados_finais - Copia (4)'!$E:$E,AW11,'resultados_finais - Copia (4)'!$P:$P,">=0"),"") -> 0 | BA11: instancias/r101,txt | BB11: =IFERROR(AVERAGEIFS($O:$O,$E:$E,AW11,$O:$O,">=0"),"") -> 291.01204 | BG11: 2
A12: tam25_cap200_tabu0_inst0_cons10 | B12: instancias/c201,txt | C12: 0 | D12: 0 | E12: 10 | F12: 25 | G12: 27 | H12: 3 | I12: 200 | J12: 0 | K12: PD | L12: 4.768 | M12: 3940.9443 | N12: 268.5325 | O12: 268.8531 | P12: 0.1194 | Q12: 0 | R12: 97 | S12: 2682 | T12: V0: [0,20,22,24,6,25,9,11,10,8,21,26] ; V1: [0,23,18,19,16,14,12,15,17,13,26] ; V2: [0,5,2,1,7,3,4,26] | V12: V0: [0,20,22,24,6,23,18,17,25,21,26] ; V1: [0,5,2,1,7,3,4,26] ; V2: [0,19,16,14,12,15,13,9,11,10,8,26] | W12: 46115.056
A13: tam25_cap200_tabu0_inst0_cons10 | B13: instancias/c202,txt | C13: 0 | D13: 0 | E13: 10 | F13: 25 | G13: 27 | H13: 3 | I13: 200 | J13: 0 | K13: PD | L13: 200.6991 | M13: 6590.9756 | N13: 271.5942 | O13: 277.7884 | P13: 2.2807 | Q13: 0 | R13: 2 | S13: 1593 | T13: V0: [0,21,12,16,14,15,13,9,11,10,26] ; V1: [0,4,3,7,1,2,5,26] ; V2: [0,20,22,24,6,23,18,19,17,25,8,26] | V13: V0: [0,20,22,24,21,26] ; V1: [0,4,3,7,1,2,5,17,13,25,8,26] ; V2: [0,6,23,18,19,16,14,12,15,9,11,10,26] | W13: 46115.135 | Y13: agoracom MIP
A14: tam25_cap200_tabu0_inst0_cons10 | B14: instancias/c203,txt | C14: 0 | D14: 0 | E14: 10 | F14: 25 | G14: 27 | H14: 3 | I14: 200 | J14: 0 | K14: PD | L14: 176.2201 | M14: 13985.747 | N14: 276.6242 | O14: -1 | R14: 0 | S14: 0 | T14: V0: [0,20,22,24,6,23,19,15,17,13,9,11,10,26] ; V1: [0,21,25,18,16,14,12,8,26] ; V2: [0,4,3,7,1,2,5,26] | V14: SEM_SEQUENCIA_BP | W14: 46115.299 | AX14: TIME
A15: tam25_cap200_tabu0_inst0_cons10 | B15: instancias/c204,txt | C15: 0 | D15: 0 | E15: 10 | F15: 25 | G15: 27 | H15: 3 | I15: 200 | J15: 0 | K15: PD | L15: 200.6124 | M15: 10859.95 | N15: 278.8716 | O15: 284.4612 | P15: 2.0044 | Q15: 0 | R15: 2 | S15: 2583 | T15: V0: [0,4,3,7,1,2,12,14,16,13,11,5,26] ; V1: [0,22,21,8,26] ; V2: [0,20,24,6,23,18,19,15,17,25,9,10,26] | V15: V0: [0,4,3,7,1,2,5,11,10,8,22,24,6,20,26] ; V1: [0,17,18,19,16,14,12,15,13,9,26] ; V2: [0,23,25,21,26] | W15: 46115.427 | AW15: heuristica | AX15: MÁXIMO | AY15: inst | AZ15: MÍNIMO | BA15: inst | BB15: MÉDIA
A16: tam25_cap200_tabu0_inst0_cons10 | B16: instancias/c205,txt | C16: 0 | D16: 0 | E16: 10 | F16: 25 | G16: 27 | H16: 3 | I16: 200 | J16: 0 | K16: PD | L16: 200.9742 | M16: 4307.8068 | N16: 268.5325 | O16: 280.8755 | P16: 4.5964 | Q16: 0 | R16: 2 | S16: 1518 | T16: V0: [0,23,18,19,16,14,12,15,17,13,26] ; V1: [0,20,22,24,6,25,9,11,10,8,21,26] ; V2: [0,5,2,1,7,3,4,26] | V16: V0: [0,20,22,24,6,23,18,19,17,25,21,8,26] ; V1: [0,2,12,16,14,15,13,9,11,10,26] ; V2: [0,5,1,7,3,4,26] | W16: 46115.479 | Y16: LITERATURA | AI16: 10 X LITERATURA COM Mip | AW16: 0 | AX16: 3999.3001 | AY16: instancias/c202,txt | AZ16: 67.9489 | BB16: 1577.3656
A17: tam25_cap200_tabu0_inst0_cons10 | B17: instancias/c206,txt | C17: 0 | D17: 0 | E17: 10 | F17: 25 | G17: 27 | H17: 3 | I17: 200 | J17: 0 | K17: PD | L17: 200.9454 | M17: 3717.1342 | N17: 266.5696 | O17: 278.4903 | P17: 4.4719 | Q17: 0 | R17: 30 | S17: 1662 | T17: V0: [0,5,2,1,7,3,4,26] ; V1: [0,20,22,24,6,23,18,19,17,25,21,26] ; V2: [0,12,14,16,15,13,9,11,10,8,26] | V17: V0: [0,20,22,24,6,23,18,19,17,25,21,8,26] ; V1: [0,5,1,7,3,4,26] ; V2: [0,2,12,14,16,15,13,9,11,10,26] | W17: 46115.524 | Y17: Problema | Z17: Nodes | AA17: Arcs | AB17: LP | AC17: IP | AD17: Vehicles | AE17: BB_Nodes | AF17: Columns | AG17: CPU | AI17: Problema | AJ17: Nodes | AK17: Arcs | AL17: LP | AM17: IP | AN17: Vehicles | AO17: BB_Nodes | AP17: Columns | AQ17: CPU | AW17: 1 | AX17: 3786.1477 | AY17: instancias/c203,txt | AZ17: 20.2125 | BB17: 1251.4237
A18: tam25_cap200_tabu0_inst0_cons10 | B18: instancias/c207,txt | C18: 0 | D18: 0 | E18: 10 | F18: 25 | G18: 27 | H18: 3 | I18: 200 | J18: 0 | K18: PD | L18: 200.6136 | M18: 3630.654 | N18: 264.6319 | O18: 274.4477 | P18: 3.7093 | Q18: 0 | R18: 176 | S18: 2382 | T18: V0: [0,5,2,1,7,3,4,26] ; V1: [0,8,9,15,19,16,14,12,11,10,26] ; V2: [0,20,22,24,6,23,18,17,13,25,21,26] | V18: V0: [0,5,2,1,7,3,4,11,9,13,25,8,26] ; V1: [0,6,23,17,18,19,15,16,14,12,10,26] ; V2: [0,20,24,22,21,26] | W18: 46115.569 | Y18: C101 | Z18: 25 | AA18: 332 | AB18: 191.3 | AC18: 191.3 | AD18: 3 | AE18: 1 | AF18: 498 | AG18: 18.6 | AI18: C101 | AJ18: 25 | AL18: 191.3 | AM18: 191.3 | AN18: 3 | AO18: 1 | AP18: =S57/AF18 -> 2.5783133 | AQ18: =M57/AG18 -> 12.595618 | AW18: 2 | AX18: 4212.7162 | AY18: instancias/c203,txt | AZ18: 23.3106 | BB18: 1214.4434
A19: tam25_cap200_tabu0_inst0_cons10 | B19: instancias/c208,txt | C19: 0 | D19: 0 | E19: 10 | F19: 25 | G19: 27 | H19: 3 | I19: 200 | J19: 0 | K19: PD | L19: 200.6399 | M19: 3607.9214 | N19: 265.8097 | O19: 273.0839 | P19: 2.7366 | Q19: 0 | R19: 58 | S19: 3141 | T19: V0: [0,12,14,16,19,15,13,9,11,10,8,26] ; V1: [0,5,2,1,7,3,4,26] ; V2: [0,20,22,24,6,23,18,17,25,21,26] | V19: V0: [0,13,15,17,25,21,8,26] ; V1: [0,20,22,24,6,23,18,19,16,14,12,9,11,10,26] ; V2: [0,5,2,1,7,3,4,26] | W19: 46115.613 | Y19: C102 | Z19: 25 | AA19: 473 | AB19: 190.3 | AC19: 190.3 | AD19: 3 | AE19: 1 | AF19: 534 | AG19: 79.7 | AI19: C102 | AJ19: 25 | AL19: 190.3 | AM19: 190.3 | AN19: 3 | AO19: 1 | AP19: =S58/AF19 -> 4.7977528 | AQ19: =M58/AG19 -> 8.63 | AW19: 3 | AX19: 3633.8025 | AY19: instancias/c202,txt | AZ19: 2.2683 | BB19: 814.73283
A20: tam25_cap200_tabu0_inst0_cons10 | B20: instancias/r101,txt | C20: 0 | D20: 0 | E20: 10 | F20: 25 | G20: 27 | H20: 8 | I20: 200 | J20: 0 | K20: PD | L20: 0.7401 | M20: 83.8383 | N20: 618.3299 | O20: 618.3299 | P20: 0 | Q20: 1 | R20: 3 | S20: 1288 | T20: V0: [0,12,9,20,1,26] ; V1: [0,11,19,10,26] ; V2: [0,18,26] ; V3: [0,23,22,4,26] ; V4: [0,7,8,17,26] ; V5: [0,5,16,6,26] ; V6: [0,2,21,3,24,25,26] ; V7: [0,14,15,13,26] | V20: V0: [0,14,15,13,26] ; V1: [0,12,9,20,1,26] ; V2: [0,23,22,4,25,26] ; V3: [0,5,16,6,26] ; V4: [0,11,19,10,26] ; V5: [0,18,26] ; V6: [0,2,21,3,24,26] ; V7: [0,7,8,17,26] | W20: 46114.686 | Y20: C103 | Z20: 25 | AA20: 569 | AB20: 190.3 | AC20: 190.3 | AD20: 3 | AE20: 1 | AF20: 447 | AG20: 134.7 | AI20: C103 | AJ20: 25 | AL20: 190.3 | AM20: 190.3 | AN20: 3 | AO20: 1 | AP20: =S59/AF20 -> 5.704698 | AQ20: =M59/AG20 -> 24.444557 | AW20: 22 | AX20: 4554.6505 | AY20: instancias/c203,txt | AZ20: 99.9047 | BB20: 2195.5316
A21: tam25_cap200_tabu0_inst0_cons10 | B21: instancias/r102,txt | C21: 0 | D21: 0 | E21: 10 | F21: 25 | G21: 27 | H21: 7 | I21: 200 | J21: 0 | K21: PD | L21: 200.5235 | M21: 3688.5971 | N21: 548.1078 | O21: 548.1078 | P21: 0 | Q21: 1 | R21: 272 | S21: 2170 | T21: V0: [0,14,16,6,13,26] ; V1: [0,3,9,20,1,26] ; V2: [0,7,11,19,10,26] ; V3: [0,2,15,22,4,25,26] ; V4: [0,18,26] ; V5: [0,8,17,5,26] ; V6: [0,21,23,24,12,26] | V21: V0: [0,14,16,6,13,26] ; V1: [0,8,17,5,26] ; V2: [0,2,15,22,4,25,26] ; V3: [0,18,26] ; V4: [0,3,9,20,1,26] ; V5: [0,21,23,24,12,26] ; V6: [0,7,11,19,10,26] | W21: 46114.731 | Y21: C104 | Z21: 25 | AA21: 604 | AB21: 186.9 | AC21: 186.9 | AD21: 3 | AE21: 1 | AF21: 485 | AG21: 223.9 | AI21: C104 | AJ21: 25 | AL21: 186.9 | AM21: 186.9 | AN21: 3 | AO21: 1 | AP21: =S60/AF21 -> 5.2268041 | AQ21: =M60/AG21 -> 4.8335176 | AW21: 10 | AX21: 3346.43 | AY21: instancias/r112,txt | AZ21: 25.3171 | BB21: 545.35546
A22: tam25_cap200_tabu0_inst0_cons10 | B22: instancias/r103,txt | C22: 0 | D22: 0 | E22: 10 | F22: 25 | G22: 27 | H22: 5 | I22: 200 | J22: 0 | K22: PD | L22: 201.4841 | M22: 1528.8382 | N22: 490.9734 | O22: 455.6982 | P22: -7.1847 | Q22: 0 | R22: 1 | S22: 1965 | T22: V0: [0,7,19,11,10,26] ; V1: [0,21,23,22,2,4,25,12,26] ; V2: [0,14,15,6,13,26] ; V3: [0,3,24,9,20,1,26] ; V4: [0,18,8,16,17,5,26] | V22: V0: [0,12,24,3,9,10,20,1,26] ; V1: [0,2,15,14,16,17,5,26] ; V2: [0,21,23,22,4,25,26] ; V3: [0,7,19,11,8,18,26] ; V4: [0,6,13,26] | W22: 46114.751 | Y22: C105 | Z22: 25 | AA22: 357 | AB22: 191.3 | AC22: 191.3 | AD22: 3 | AE22: 1 | AF22: 531 | AG22: 25.6 | AI22: C105 | AJ22: 25 | AL22: 191.3 | AM22: 191.3 | AN22: 3 | AO22: 1 | AP22: =S61/AF22 -> 4.4350282 | AQ22: =M61/AG22 -> 29.717805
A23: tam25_cap200_tabu0_inst0_cons10 | B23: instancias/r104,txt | C23: 0 | D23: 0 | E23: 10 | F23: 25 | G23: 27 | H23: 4 | I23: 200 | J23: 0 | K23: PD | L23: 200.8732 | M23: 848.9515 | N23: -1 | O23: 417.9612 | R23: 1 | S23: 1848 | T23: SEM_SEQUENCIA_EXATO | V23: V0: [0,2,15,14,16,17,5,26] ; V1: [0,7,19,11,8,18,6,13,26] ; V2: [0,21,22,23,4,25,26] ; V3: [0,12,24,3,9,20,10,1,26] | W23: 46114.764 | Y23: C106 | Z23: 25 | AA23: 336 | AB23: 191.3 | AC23: 191.3 | AD23: 3 | AE23: 1 | AF23: 447 | AG23: 20.7 | AI23: C106 | AJ23: 25 | AL23: 191.3 | AM23: 191.3 | AN23: 3 | AO23: 1 | AP23: =S62/AF23 -> 2.7651007 | AQ23: =M62/AG23 -> 8.7605556
A24: tam25_cap200_tabu0_inst0_cons10 | B24: instancias/r105,txt | C24: 0 | D24: 0 | E24: 10 | F24: 25 | G24: 27 | H24: 6 | I24: 200 | J24: 0 | K24: PD | L24: 26.0318 | M24: 267.1819 | N24: 531.5386 | O24: 531.5386 | P24: 0 | Q24: 1 | R24: 1 | S24: 1404 | T24: V0: [0,5,14,16,6,26] ; V1: [0,12,9,3,24,25,26] ; V2: [0,2,15,13,26] ; V3: [0,21,23,22,4,26] ; V4: [0,7,18,8,17,26] ; V5: [0,19,11,10,20,1,26] | V24: V0: [0,12,9,3,24,26] ; V1: [0,5,14,16,6,26] ; V2: [0,7,18,8,17,26] ; V3: [0,19,11,10,20,1,26] ; V4: [0,2,15,13,26] ; V5: [0,21,23,22,4,25,26] | W24: 46114.767 | Y24: C107 | Z24: 25 | AA24: 377 | AB24: 191.3 | AC24: 191.3 | AD24: 3 | AE24: 1 | AF24: 514 | AG24: 31.7 | AI24: C107 | AJ24: 25 | AL24: 191.3 | AM24: 191.3 | AN24: 3 | AO24: 1 | AP24: =S63/AF24 -> 5.6848249 | AQ24: =M63/AG24 -> 34.91906
A25: tam25_cap200_tabu0_inst0_cons10 | B25: instancias/r106,txt | C25: 0 | D25: 0 | E25: 10 | F25: 25 | G25: 27 | H25: 5 | I25: 200 | J25: 0 | K25: PD | L25: 201.2862 | M25: 3642.4569 | N25: 466.4802 | O25: 466.4802 | P25: 0 | Q25: 1 | R25: 151 | S25: 2525 | T25: V0: [0,2,15,23,22,4,25,21,26] ; V1: [0,14,16,6,13,26] ; V2: [0,7,19,11,10,26] ; V3: [0,18,8,17,5,26] ; V4: [0,1,9,20,3,24,12,26] | V25: V0: [0,18,8,17,5,26] ; V1: [0,14,16,6,13,26] ; V2: [0,2,15,23,22,4,25,21,26] ; V3: [0,7,19,11,10,26] ; V4: [0,1,9,20,3,24,12,26] | W25: 46114.812 | Y25: C108 | Z25: 25 | AA25: 431 | AB25: 191.3 | AC25: 191.3 | AD25: 3 | AE25: 1 | AF25: 513 | AG25: 43.1 | AI25: C108 | AJ25: 25 | AL25: 191.3 | AM25: 191.3 | AN25: 3 | AO25: 1 | AP25: =S64/AF25 -> 5.2982456 | AQ25: =M64/AG25 -> 22.461522 | AV25: COM MIP
A26: tam25_cap200_tabu0_inst0_cons10 | B26: instancias/r107,txt | C26: 0 | D26: 0 | E26: 10 | F26: 25 | G26: 27 | H26: 4 | I26: 200 | J26: 0 | K26: PD | L26: 200.8063 | M26: 1103.3267 | N26: -1 | O26: 425.2685 | R26: 1 | S26: 1860 | T26: SEM_SEQUENCIA_EXATO | V26: V0: [0,18,7,11,19,8,17,16,5,26] ; V1: [0,12,3,9,20,10,1,26] ; V2: [0,21,23,22,4,25,24,26] ; V3: [0,2,15,14,6,13,26] | W26: 46114.827 | Y26: C109 | Z26: 25 | AA26: 482 | AB26: 189.4 | AC26: 191.3 | AD26: 3 | AE26: 3 | AF26: 1747 | AG26: 585.4 | AI26: C109 | AJ26: 25 | AL26: 189.4 | AM26: 191.3 | AN26: 3 | AO26: 3 | AP26: =S65/AF26 -> 0.86891815 | AQ26: =M65/AG26 -> 1.2073994 | AW26: GAP
A27: tam25_cap200_tabu0_inst0_cons10 | B27: instancias/r108,txt | C27: 0 | D27: 0 | E27: 10 | F27: 25 | G27: 27 | H27: 4 | I27: 200 | J27: 0 | K27: PD | L27: 201.0159 | M27: 3735.8646 | N27: 467.1724 | O27: 398.2947 | P27: -14.7435 | Q27: 0 | R27: 5 | S27: 1952 | T27: V0: [0,19,11,7,8,17,18,26] ; V1: [0,10,20,9,3,12,1,26] ; V2: [0,5,16,14,6,13,21,26] ; V3: [0,2,15,23,22,4,25,24,26] | V27: V0: [0,21,22,23,4,25,24,26] ; V1: [0,2,15,14,16,17,5,6,13,26] ; V2: [0,7,10,11,19,8,18,26] ; V3: [0,1,20,9,3,12,26] | W27: 46114.872 | AV27: heuristica | AW27: MÁXIMO | AX27: inst | AY27: MÍNIMO | AZ27: inst | BA27: MÉDIA
A28: tam25_cap200_tabu0_inst0_cons10 | B28: instancias/r109,txt | C28: 0 | D28: 0 | E28: 10 | F28: 25 | G28: 27 | H28: 5 | I28: 200 | J28: 0 | K28: PD | L28: 111.6148 | M28: 792.7108 | N28: 442.6252 | O28: 442.6252 | P28: 0 | Q28: 1 | R28: 1 | S28: 2085 | T28: V0: [0,2,15,14,16,17,13,26] ; V1: [0,5,8,18,6,26] ; V2: [0,21,22,23,4,25,24,26] ; V3: [0,12,3,9,20,1,26] ; V4: [0,7,19,11,10,26] | V28: V0: [0,21,22,23,4,25,24,26] ; V1: [0,2,15,14,16,17,13,26] ; V2: [0,12,3,9,20,1,26] ; V3: [0,7,19,11,10,26] ; V4: [0,5,8,18,6,26] | W28: 46114.883 | Y28: agoracom MIP | AV28: 0 | AW28: =IFERROR(_xlfn.MAXIFS($P$57:$P$76,$E$57:$E$76,AV28),"") -> 0 | AX28: instancias/c202,txt | AY28: =IFERROR(_xlfn.MINIFS('resultados_finais - Copia (4)'!$P:$P,'resultados_finais - Copia (4)'!$E:$E,AV28,'resultados_finais - Copia (4)'!$P:$P,">=0"),"") -> 0 | AZ28: instancias/r101,txt | BA28: =IFERROR(AVERAGEIFS($O:$O,$E:$E,AV28,$O:$O,">=0"),"")
A29: tam25_cap200_tabu0_inst0_cons10 | B29: instancias/r110,txt | C29: 0 | D29: 0 | E29: 10 | F29: 25 | G29: 27 | H29: 4 | I29: 200 | J29: 0 | K29: PD | L29: 201.1952 | M29: 4107.8911 | N29: -1 | O29: 445.8722 | R29: 31 | S29: 2816 | T29: SEM_SEQUENCIA_EXATO | V29: V0: [0,18,8,17,6,26] ; V1: [0,5,16,14,15,22,23,13,26] ; V2: [0,11,19,7,10,20,9,1,26] ; V3: [0,2,21,12,3,24,25,4,26] | W29: 46114.933 | AU29: inserção com melhoria | AV29: 1 | AW29: =IFERROR(_xlfn.MAXIFS($P$57:$P$76,$E$57:$E$76,AV29),"") -> 0 | AX29: instancias/c202,txt | AY29: =IFERROR(_xlfn.MINIFS('resultados_finais - Copia (4)'!$P:$P,'resultados_finais - Copia (4)'!$E:$E,AV29,'resultados_finais - Copia (4)'!$P:$P,">=0"),"") -> 0 | AZ29: instancias/r101,txt | BA29: =IFERROR(AVERAGEIFS($O:$O,$E:$E,AV29,$O:$O,">=0"),"")
A30: tam25_cap200_tabu0_inst0_cons10 | B30: instancias/r111,txt | C30: 0 | D30: 0 | E30: 10 | F30: 25 | G30: 27 | H30: 4 | I30: 200 | J30: 0 | K30: PD | L30: 200.9118 | M30: 2720.2744 | N30: -1 | O30: 429.6968 | R30: 25 | S30: 1960 | T30: SEM_SEQUENCIA_EXATO | V30: V0: [0,2,15,14,16,6,13,26] ; V1: [0,7,11,19,8,18,17,5,26] ; V2: [0,21,23,22,4,25,24,26] ; V3: [0,12,3,9,20,10,1,26] | W30: 46114.966 | AU30: vns_ com acrescimo | AV30: 2 | AW30: =IFERROR(_xlfn.MAXIFS($P$57:$P$76,$E$57:$E$76,AV30),"") -> 0 | AX30: instancias/c202,txt | AY30: =IFERROR(_xlfn.MINIFS('resultados_finais - Copia (4)'!$P:$P,'resultados_finais - Copia (4)'!$E:$E,AV30,'resultados_finais - Copia (4)'!$P:$P,">=0"),"") -> 0 | AZ30: instancias/r101,txt | BA30: =IFERROR(AVERAGEIFS($O:$O,$E:$E,AV30,$O:$O,">=0"),"")
A31: tam25_cap200_tabu0_inst0_cons10 | B31: instancias/r112,txt | C31: 0 | D31: 0 | E31: 10 | F31: 25 | G31: 27 | H31: 4 | I31: 200 | J31: 0 | K31: PD | L31: 200.8882 | M31: 3610.0806 | N31: 394.1013 | O31: 395.0909 | P31: 0.2511 | Q31: 0 | R31: 61 | S31: 2044 | T31: V0: [0,18,8,7,19,11,10,26] ; V1: [0,21,22,23,4,25,24,26] ; V2: [0,2,15,14,16,17,5,6,13,26] ; V3: [0,12,3,9,20,1,26] | V31: V0: [0,21,22,23,25,4,26] ; V1: [0,2,15,14,16,17,5,6,13,26] ; V2: [0,18,8,7,19,11,10,26] ; V3: [0,12,24,3,9,20,1,26] | W31: 46115.01 | AU31: sem pd | AV31: 3 | AW31: =IFERROR(_xlfn.MAXIFS($P$57:$P$76,$E$57:$E$76,AV31),"") -> 0 | AX31: instancias/c201,txt | AY31: =IFERROR(_xlfn.MINIFS('resultados_finais - Copia (4)'!$P:$P,'resultados_finais - Copia (4)'!$E:$E,AV31,'resultados_finais - Copia (4)'!$P:$P,">=0"),"") -> 0 | AZ31: instancias/r101,txt | BA31: =IFERROR(AVERAGEIFS($O:$O,$E:$E,AV31,$O:$O,">=0"),"")
B32: mesma semente | Y32: LITERATURA | AI32: 10 X LITERATURA COM Mip | AT32: construtivas | AU32: apenas pd | AV32: 22 | AW32: =IFERROR(_xlfn.MAXIFS($P$57:$P$76,$E$57:$E$76,AV32),"") -> 0 | AX32: instancias/r102,txt | AY32: =IFERROR(_xlfn.MINIFS('resultados_finais - Copia (4)'!$P:$P,'resultados_finais - Copia (4)'!$E:$E,AV32,'resultados_finais - Copia (4)'!$P:$P,">=0"),"") -> 0 | AZ32: instancias/r101,txt | BA32: =IFERROR(AVERAGEIFS($O:$O,$E:$E,AV32,$O:$O,">=0"),"")
B33: com mip | Y33: Problema | Z33: Nodes | AA33: Arcs | AB33: LP | AC33: IP | AD33: Vehicles | AE33: BB_Nodes | AF33: Columns | AG33: CPU | AI33: Problema | AJ33: Nodes | AK33: Arcs | AL33: LP | AM33: IP | AN33: Vehicles | AO33: BB_Nodes | AP33: Columns | AQ33: CPU | AU33: todas | AV33: 10 | AW33: =IFERROR(_xlfn.MAXIFS($P$57:$P$76,$E$57:$E$76,AV33),"") -> 8.4077 | AX33: instancias/c109,txt | AY33: =IFERROR(_xlfn.MINIFS('resultados_finais - Copia (4)'!$P:$P,'resultados_finais - Copia (4)'!$E:$E,AV33,'resultados_finais - Copia (4)'!$P:$P,">=0"),"") -> 0 | AZ33: instancias/r101,txt | BA33: =IFERROR(AVERAGEIFS($O:$O,$E:$E,AV33,$O:$O,">=0"),"") -> 291.01204
A34: tam25_cap200_tabu0_inst0_cons10 | B34: instancias/r101,txt | C34: 0 | D34: 0 | E34: 10 | F34: 25 | G34: 27 | H34: 8 | I34: 200 | J34: 0 | K34: PD | L34: 0.7396 | M34: 25.3171 | N34: 618,3299 | O34: 618,3299 | P34: 0 | Q34: 1 | R34: 1 | S34: 1176 | T34: V0: [0,12,9,20,1,26] ; V1: [0,11,19,10,26] ; V2: [0,18,26] ; V3: [0,23,22,4,26] ; V4: [0,7,8,17,26] ; V5: [0,5,16,6,26] ; V6: [0,2,21,3,24,25,26] ; V7: [0,14,15,13,26] | U34: V0: [0,12,9,20,1,26] ; V1: [0,7,8,17,26] ; V2: [0,23,22,4,26] ; V3: [0,2,21,3,24,25,26] ; V4: [0,14,15,13,26] ; V5: [0,18,26] ; V6: [0,11,19,10,26] ; V7: [0,5,16,6,26] | V34: 46107.82 | Y34: R101 | Z34: 25 | AA34: 227 | AB34: 617.1 | AC34: 617.1 | AD34: 8 | AE34: 1 | AF34: 78 | AG34: 5.8 | AI34: R101 | AJ34: 25 | AL34: 191.3 | AM34: =(O34-AC34)/AC34 -> 0.0019930319 | AN34: 3 | AO34: 1 | AP34: =S34/AF34 -> 15.076923 | AQ34: =M34/AG34 -> 4.3650172
A35: tam25_cap200_tabu0_inst0_cons10 | B35: instancias/r102,txt | C35: 0 | D35: 0 | E35: 10 | F35: 25 | G35: 27 | H35: 7 | I35: 200 | J35: 0 | K35: PD | L35: 1200.9863 | M35: 1620.0409 | N35: 548,1078 | O35: 548,1078 | P35: 0 | Q35: 1 | R35: 2585 | S35: 2170 | T35: V0: [0,14,16,6,13,26] ; V1: [0,3,9,20,1,26] ; V2: [0,7,11,19,10,26] ; V3: [0,2,15,22,4,25,26] ; V4: [0,18,26] ; V5: [0,8,17,5,26] ; V6: [0,21,23,24,12,26] | U35: V0: [0,3,9,20,1,26] ; V1: [0,8,17,5,26] ; V2: [0,21,23,24,12,26] ; V3: [0,7,11,19,10,26] ; V4: [0,18,26] ; V5: [0,14,16,6,13,26] ; V6: [0,2,15,22,4,25,26] | V35: 46107.852 | Y35: R102 | Z35: 25 | AA35: 404 | AB35: 546.4 | AC35: 547.1 | AD35: 7 | AE35: 3 | AF35: 165 | AG35: 20.3 | AI35: R102 | AJ35: 25 | AL35: 190.3 | AM35: =(O35-AC35)/AC35 -> 0.0018420764 | AN35: 3 | AO35: 1 | AP35: =S35/AF35 -> 13.151515 | AQ35: =M35/AG35 -> 79.80497
A36: tam25_cap200_tabu0_inst0_cons10 | B36: instancias/r103,txt | C36: 0 | D36: 0 | E36: 10 | F36: 25 | G36: 27 | H36: 5 | I36: 200 | J36: 0 | K36: PD | L36: 1201.1936 | M36: 185.2481 | N36: 468,2479 | O36: 455,6982 | P36: -2.6801 | Q36: 0 | R36: 1 | S36: 1525 | T36: V0: [0,7,19,11,10,26] ; V1: [0,2,21,23,22,4,25,26] ; V2: [0,14,15,6,13,26] ; V3: [0,1,20,9,3,24,12,26] ; V4: [0,18,8,17,16,5,26] | U36: V0: [0,12,24,3,9,10,20,1,26] ; V1: [0,21,23,22,4,25,26] ; V2: [0,7,19,11,8,18,26] ; V3: [0,2,15,14,16,17,5,26] ; V4: [0,6,13,26] | V36: 46107.869 | Y36: R103 | Z36: 25 | AA36: 510 | AB36: 454.6 | AC36: 454.6 | AD36: 5 | AE36: 1 | AF36: 246 | AG36: 22.2 | AI36: R103 | AJ36: 25 | AL36: 190.3 | AM36: =(O36-AC36)/AC36 -> 0.0024157501 | AN36: 3 | AO36: 1 | AP36: =S36/AF36 -> 6.199187 | AQ36: =M36/AG36 -> 8.344509 | AW36: TIME
A37: tam25_cap200_tabu0_inst0_cons10 | B37: instancias/r104,txt | C37: 0 | D37: 0 | E37: 10 | F37: 25 | G37: 27 | H37: 4 | I37: 200 | J37: 0 | K37: PD | L37: 1201.6167 | M37: 162.7161 | N37: 453,6869 | O37: 417,9612 | P37: -7.8745 | Q37: 0 | R37: 3 | S37: 1732 | T37: V0: [0,15,16,14,13,26] ; V1: [0,21,22,23,4,2,6,26] ; V2: [0,7,19,11,8,17,5,18,26] ; V3: [0,1,10,20,9,3,24,25,12,26] | U37: V0: [0,12,24,3,9,20,10,1,26] ; V1: [0,2,15,14,16,17,5,26] ; V2: [0,7,19,11,8,18,6,13,26] ; V3: [0,21,22,23,4,25,26] | V37: 46107.884 | Y37: R104 | Z37: 25 | AA37: 559 | AB37: 416.9 | AC37: 416.9 | AD37: 4 | AE37: 1 | AF37: 419 | AG37: 46 | AI37: R104 | AJ37: 25 | AL37: 186.9 | AM37: =(O37-AC37)/AC37 -> 0.0025454545 | AN37: 3 | AO37: 1 | AP37: =S37/AF37 -> 4.1336516 | AQ37: =M37/AG37 -> 3.5373065 | AV37: heuristica | AW37: MÁXIMO | AX37: inst | AY37: MÍNIMO | AZ37: inst | BA37: MÉDIA
A38: tam25_cap200_tabu0_inst0_cons10 | B38: instancias/r105,txt | C38: 0 | D38: 0 | E38: 10 | F38: 25 | G38: 27 | H38: 6 | I38: 200 | J38: 0 | K38: PD | L38: 17.6753 | M38: 45.5649 | N38: 531,5386 | O38: 531,5386 | P38: 0 | Q38: 1 | R38: 1 | S38: 1242 | T38: V0: [0,5,14,16,6,26] ; V1: [0,12,9,3,24,25,26] ; V2: [0,2,15,13,26] ; V3: [0,21,23,22,4,26] ; V4: [0,7,18,8,17,26] ; V5: [0,19,11,10,20,1,26] | U38: V0: [0,19,11,10,20,1,26] ; V1: [0,21,23,22,4,26] ; V2: [0,7,18,8,17,26] ; V3: [0,2,15,13,26] ; V4: [0,12,9,3,24,25,26] ; V5: [0,5,14,16,6,26] | V38: 46107.885 | Y38: R105 | Z38: 25 | AA38: 303 | AB38: 526 | AC38: 530.5 | AD38: 6 | AE38: 7 | AF38: 554 | AG38: 22.6 | AI38: R105 | AJ38: 25 | AL38: 191.3 | AM38: =(O38-AC38)/AC38 -> 0.0019577757 | AN38: 3 | AO38: 1 | AP38: =S38/AF38 -> 2.2418773 | AQ38: =M38/AG38 -> 2.016146 | AV38: 0 | AW38: 3999.3001 | AX38: instancias/c202,txt | AY38: 67.9489 | BA38: 1577.3656
A39: tam25_cap200_tabu0_inst0_cons10 | B39: instancias/r106,txt | C39: 0 | D39: 0 | E39: 10 | F39: 25 | G39: 27 | H39: 5 | I39: 200 | J39: 0 | K39: PD | L39: 1096.8556 | M39: 896.2332 | N39: 466,4802 | O39: 466,4802 | P39: 0 | Q39: 1 | R39: 135 | S39: 2515 | T39: V0: [0,2,15,23,22,4,25,21,26] ; V1: [0,14,16,6,13,26] ; V2: [0,7,19,11,10,26] ; V3: [0,18,8,17,5,26] ; V4: [0,1,9,20,3,24,12,26] | U39: V0: [0,2,15,23,22,4,25,21,26] ; V1: [0,7,19,11,10,26] ; V2: [0,1,9,20,3,24,12,26] ; V3: [0,14,16,6,13,26] ; V4: [0,18,8,17,5,26] | V39: 46107.908 | Y39: R106 | Z39: 25 | AA39: 458 | AB39: 457.3 | AC39: 467.4 | AD39: 5 | AE39: 15 | AF39: 2451 | AG39: 205.2 | AI39: R106 | AJ39: 25 | AL39: 191.3 | AM39: =(O39-AC39)/AC39 -> -0.0019679076 | AN39: 3 | AO39: 1 | AP39: =S39/AF39 -> 1.0261118 | AQ39: =M39/AG39 -> 4.3676082 | AV39: 1 | AW39: 3786.1477 | AX39: instancias/c203,txt | AY39: 20.2125 | BA39: 1251.4237
A40: tam25_cap200_tabu0_inst0_cons10 | B40: instancias/r107,txt | C40: 0 | D40: 0 | E40: 10 | F40: 25 | G40: 27 | H40: 4 | I40: 200 | J40: 0 | K40: PD | L40: 1201.4687 | M40: 191.867 | N40: 429,2004 | O40: 425,2685 | P40: -0.9161 | Q40: 0 | R40: 1 | S40: 1816 | T40: V0: [0,6,16,14,13,26] ; V1: [0,18,7,11,19,8,17,5,26] ; V2: [0,2,15,23,22,4,25,21,26] ; V3: [0,12,24,3,9,20,10,1,26] | U40: V0: [0,2,15,14,6,13,26] ; V1: [0,21,23,22,4,25,24,26] ; V2: [0,18,7,11,19,8,17,16,5,26] ; V3: [0,12,3,9,20,10,1,26] | V40: 46107.924 | Y40: R107 | Z40: 25 | AA40: 542 | AB40: 423 | AC40: 424.3 | AD40: 4 | AE40: 21 | AF40: 3191 | AG40: 304.1 | AI40: R107 | AJ40: 25 | AL40: 191.3 | AM40: =(O40-AC40)/AC40 -> 0.0022825831 | AN40: 3 | AO40: 1 | AP40: =S40/AF40 -> 0.5691006 | AQ40: =M40/AG40 -> 0.6309339 | AV40: 2 | AW40: 4212.7162 | AX40: instancias/c203,txt | AY40: 23.3106 | BA40: 1214.4434
...

Sheet artigo
C3: ARTIGO BASE
B4: Problema | C4: Nodes | D4: Arcs | E4: LP | F4: IP | G4: Vehicles | H4: BB_Nodes | I4: Columns | J4: CPU
B5: R101 | C5: 25 | D5: 227 | E5: 617.1 | F5: 617.1 | G5: 8 | H5: 1 | I5: 78 | J5: 5.8
B6: R101 | C6: 50 | D6: 817 | E6: 1034.6 | F6: 1035.2 | G6: 12 | H6: 11 | I6: 1395 | J6: 66.7
B7: R101 | C7: 100 | D7: 3272 | E7: 1604.5 | F7: 1607.7 | G7: 18 | H7: 23 | I7: 8596 | J7: 1064.2
B8: R102 | C8: 25 | D8: 404 | E8: 546.4 | F8: 547.1 | G8: 7 | H8: 3 | I8: 165 | J8: 20.3
B9: R102 | C9: 50 | D9: 1437 | E9: 904.6 | F9: 904.6 | G9: 11 | H9: 1 | I9: 591 | J9: 67.8
B10: R102 | C10: 100 | D10: 5336 | E10: 1434 | F10: 1434 | G10: 17 | H10: 1 | I10: 2126 | J10: 756.9
B11: R103 | C11: 25 | D11: 510 | E11: 454.6 | F11: 454.6 | G11: 5 | H11: 1 | I11: 246 | J11: 22.2
B12: R103 | C12: 50 | D12: 1859 | E12: 765.4 | F12: 772.5 | G12: 9 | H12: 173 | I12: 37330 | J12: 8939.1
B13: R104 | C13: 25 | D13: 559 | E13: 416.9 | F13: 416.9 | G13: 4 | H13: 1 | I13: 419 | J13: 46
B14: R105 | C14: 25 | D14: 303 | E14: 526 | F14: 530.5 | G14: 6 | H14: 7 | I14: 554 | J14: 22.6
B15: R105 | C15: 50 | D15: 1076 | E15: 891.7 | F15: 899.3 | G15: 9 | H15: 33 | I15: 4458 | J15: 362.6
B16: R106 | C16: 25 | D16: 458 | E16: 457.3 | F16: 467.4 | G16: 5 | H16: 15 | I16: 2451 | J16: 205.2
... B56: RC108 | C56: 25 | D56: 617 | E56: 280.3 | F56: 294.5 | G56: 3 | H56: 11 | I56: 1126 | J56: 256

Sheet variacao_NOIMPROVE
B4: SEM MIP | C4: ninst | D4: tem_janelas | E4: heuristica_retirada | F4: tamanho_clientes | G4: nos_rede | H4: veiculos | I4: capacidade | J4: tabu | K4: tipo_geracao | L4: tempo_exato | M4: tempo_bp | N4: fo_exato | O4: fo_bp | P4: gap_pct | Q4: igual_exato | R4: nos_bp | T4: colunas_bp | V4: NO IMPROVE
B5: tam25_cap200_tabu0_inst0_cons10 | C5: instancias/c101N,txt | D5: 0 | E5: 0 | F5: 10 | G5: 25 | H5: 27 | I5: 3 | J5: 200 | K5: 0 | L5: PD | M5: 168.2456 | N5: 191.3 | O5: 191.3 | P5: 0 | Q5: 1 | R5: 1 | T5: 996 | U5: False | V5: 4 | W5: V0: [0,13,17,18,19,15,16,14,12,26] ; V1: [0,20,24,25,23,22,21,26] ; V2: [0,5,3,7,8,10,11,9,6,4,2,1,26] | X5: V0: [0,5,3,7,8,10,11,9,6,4,2,1,26] ; V1: [0,20,24,25,23,22,21,26] ; V2: [0,13,17,18,19,15,16,14,12,26] | Y5: 46119.183
B6: tam25_cap200_tabu0_inst0_cons10 | C6: instancias/c101N,txt | D6: 0 | E6: 0 | F6: 10 | G6: 25 | H6: 27 | I6: 3 | J6: 200 | K6: 0 | L6: PD | M6: 263.952 | N6: 191.3 | O6: 191.3 | P6: 0 | Q6: 1 | R6: 1 | T6: 1446 | U6: True | V6: 4 | W6: V0: [0,13,17,18,19,15,16,14,12,26] ; V1: [0,20,24,25,23,22,21,26] ; V2: [0,5,3,7,8,10,11,9,6,4,2,1,26] | X6: V0: [0,13,17,18,19,15,16,14,12,26] ; V1: [0,20,24,25,23,22,21,26] ; V2: [0,5,3,7,8,10,11,9,6,4,2,1,26] | Y6: 46119.186
B7: tam25_cap200_tabu0_inst0_cons10 | C7: instancias/c101N,txt | D7: 0 | E7: 0 | F7: 10 | G7: 25 | H7: 27 | I7: 3 | J7: 200 | K7: 0 | L7: PD | M7: 163.5549 | N7: 191.3 | O7: 191.3 | P7: 0 | Q7: 1 | R7: 1 | T7: 996 | U7: False | V7: 6 | W7: V0: [0,13,17,18,19,15,16,14,12,26] ; V1: [0,20,24,25,23,22,21,26] ; V2: [0,5,3,7,8,10,11,9,6,4,2,1,26] | X7: V0: [0,5,3,7,8,10,11,9,6,4,2,1,26] ; V1: [0,20,24,25,23,22,21,26] ; V2: [0,13,17,18,19,15,16,14,12,26] | Y7: 46119.188
B8: tam25_cap200_tabu0_inst0_cons10 | C8: instancias/c101N,txt | D8: 0 | E8: 0 | F8: 10 | G8: 25 | H8: 27 | I8: 3 | J8: 200 | K8: 0 | L8: PD | M8: 286.0176 | N8: 191.3 | O8: 191.3 | P8: 0 | Q8: 1 | R8: 1 | T8: 1446 | U8: True | V8: 6 | W8: V0: [0,13,17,18,19,15,16,14,12,26] ; V1: [0,20,24,25,23,22,21,26] ; V2: [0,5,3,7,8,10,11,9,6,4,2,1,26] | X8: V0: [0,13,17,18,19,15,16,14,12,26] ; V1: [0,20,24,25,23,22,21,26] ; V2: [0,5,3,7,8,10,11,9,6,4,2,1,26] | Y8: 46119.191
B9: tam25_cap200_tabu0_inst0_cons10 | C9: instancias/c102,txt | D9: 0 | E9: 0 | F9: 10 | G9: 25 | H9: 27 | I9: 3 | J9: 200 | K9: 0 | L9: PD | M9: 457.3505 | N9: 190.3 | O9: 190.3 | P9: 0 | Q9: 1 | R9: 1 | T9: 2001 | U9: False | V9: 2 | W9: V0: [0,13,17,18,19,15,16,14,12,26] ; V1: [0,20,24,25,23,22,21,26] ; V2: [0,7,8,10,11,9,6,4,2,1,3,5,26] | X9: V0: [0,13,17,18,19,15,16,14,12,26] ; V1: [0,20,24,25,23,22,21,26] ; V2: [0,7,8,10,11,9,6,4,2,1,3,5,26] | Y9: 46119.208
B10: tam25_cap200_tabu0_inst0_cons10 | C10: instancias/c102,txt | D10: 0 | E10: 0 | F10: 10 | G10: 25 | H10: 27 | I10: 3 | J10: 200 | K10: 0 | L10: PD | M10: 435.1895 | N10: 190.3 | O10: 190.3 | P10: 0 | Q10: 1 | R10: 1 | T10: 2574 | U10: True | V10: 2 | W10: V0: [0,13,17,18,19,15,16,14,12,26] ; V1: [0,20,24,25,23,22,21,26] ; V2: [0,7,8,10,11,9,6,4,2,1,3,5,26] | X10: V0: [0,13,17,18,19,15,16,14,12,26] ; V1: [0,20,24,25,23,22,21,26] ; V2: [0,7,8,10,11,9,6,4,2,1,3,5,26] | Y10: 46119.213
B11: tam25_cap200_tabu0_inst0_cons10 | C11: instancias/c102,txt | D11: 0 | E11: 0 | F11: 10 | G11: 25 | H11: 27 | I11: 3 | J11: 200 | K11: 0 | L11: PD | M11: 408.573 | N11: 190.3 | O11: 190.3 | P11: 0 | Q11: 1 | R11: 1 | T11: 2001 | U11: False | V11: 4 | W11: V0: [0,13,17,18,19,15,16,14,12,26] ; V1: [0,20,24,25,23,22,21,26] ; V2: [0,7,8,10,11,9,6,4,2,1,3,5,26] | X11: V0: [0,13,17,18,19,15,16,14,12,26] ; V1: [0,20,24,25,23,22,21,26] ; V2: [0,7,8,10,11,9,6,4,2,1,3,5,26] | Y11: 46119.218
B12: tam25_cap200_tabu0_inst0_cons10 | C12: instancias/c102,txt | D12: 0 | E12: 0 | F12: 10 | G12: 25 | H12: 27 | I12: 3 | J12: 200 | K12: 0 | L12: PD | M12: 434.9023 | N12: 190.3 | O12: 190.3 | P12: 0 | Q12: 1 | R12: 1 | T12: 2574 | U12: True | V12: 4 | W12: V0: [0,13,17,18,19,15,16,14,12,26] ; V1: [0,20,24,25,23,22,21,26] ; V2: [0,7,8,10,11,9,6,4,2,1,3,5,26] | X12: V0: [0,13,17,18,19,15,16,14,12,26] ; V1: [0,20,24,25,23,22,21,26] ; V2: [0,7,8,10,11,9,6,4,2,1,3,5,26] | Y12: 46119.223
B13: tam25_cap200_tabu0_inst0_cons10 | C13: instancias/c102,txt | D13: 0 | E13: 0 | F13: 10 | G13: 25 | H13: 27 | I13: 3 | J13: 200 | K13: 0 | L13: PD | M13: 407.7031 | N13: 190.3 | O13: 190.3 | P13: 0 | Q13: 1 | R13: 1 | T13: 2001 | U13: False | V13: 6 | W13: V0: [0,13,17,18,19,15,16,14,12,26] ; V1: [0,20,24,25,23,22,21,26] ; V2: [0,7,8,10,11,9,6,4,2,1,3,5,26] | X13: V0: [0,13,17,18,19,15,16,14,12,26] ; V1: [0,20,24,25,23,22,21,26] ; V2: [0,7,8,10,11,9,6,4,2,1,3,5,26] | Y13: 46119.227
B14: tam25_cap200_tabu0_inst0_cons10 | C14: instancias/c102,txt | D14: 0 | E14: 0 | F14: 10 | G14: 25 | H14: 27 | I14: 3 | J14: 200 | K14: 0 | L14: PD | M14: 433.9203 | N14: 190.3 | O14: 190.3 | P14: 0 | Q14: 1 | R14: 1 | T14: 2574 | U14: True | V14: 6 | W14: V0: [0,13,17,18,19,15,16,14,12,26] ; V1: [0,20,24,25,23,22,21,26] ; V2: [0,7,8,10,11,9,6,4,2,1,3,5,26] | X14: V0: [0,13,17,18,19,15,16,14,12,26] ; V1: [0,20,24,25,23,22,21,26] ; V2: [0,7,8,10,11,9,6,4,2,1,3,5,26] | Y14: 46119.232
B15: tam25_cap200_tabu0_inst0_cons10 | C15: instancias/c102,txt | D15: 0 | E15: 0 | F15: 10 | G15: 25 | H15: 27 | I15: 3 | J15: 200 | K15: 0 | L15: PD | M15: 407.0304 | N15: 190.3 | O15: 190.3 | P15: 0 | Q15: 1 | R15: 1 | T15: 2001 | U15: False | V15: 8 | W15: V0: [0,13,17,18,19,15,16,14,12,26] ; V1: [0,20,24,25,23,22,21,26] ; V2: [0,7,8,10,11,9,6,4,2,1,3,5,26] | X15: V0: [0,13,17,18,19,15,16,14,12,26] ; V1: [0,20,24,25,23,22,21,26] ; V2: [0,7,8,10,11,9,6,4,2,1,3,5,26] | Y15: 46119.237
B16: tam25_cap200_tabu0_inst0_cons10 | C16: instancias/c102,txt | D16: 0 | E16: 0 | F16: 10 | G16: 25 | H16: 27 | I16: 3 | J16: 200 | K16: 0 | L16: PD | M16: 434.1616 | N16: 190.3 | O16: 190.3 | P16: 0 | Q16: 1 | R16: 1 | T16: 2574 | U16: True | V16: 8 | W16: V0: [0,13,17,18,19,15,16,14,12,26] ; V1: [0,20,24,25,23,22,21,26] ; V2: [0,7,8,10,11,9,6,4,2,1,3,5,26] | X16: V0: [0,13,17,18,19,15,16,14,12,26] ; V1: [0,20,24,25,23,22,21,26] ; V2: [0,7,8,10,11,9,6,4,2,1,3,5,26] | Y16: 46119.242
... B48: tam25_cap200_tabu0_inst0_cons10 | C48: instancias/c107,txt | D48: 0 | E48: 0 | F48: 10 | G48: 25 | H48: 27 | I48: 3 | J48: 200 | K48: 0 | L48: PD | M48: 187.349 | N48: 191.3 | O48: 191.3 | P48: 0 | Q48: 1 | R48: 1 | T48: 1644 | U48: False | V48: 2 | W48: V0: [0,20,24,25,23,22,21,26] ; V1: [0,5,3,7,8,10,11,9,6,4,2,1,26] ; V2: [0,13,17,18,19,15,16,14,12,26] | X48: V0: [0,5,3,7,8,10,11,9,6,4,2,1,26] ; V1: [0,20,24,25,23,22,21,26] ; V2: [0,13,17,18,19,15,16,14,12,26] | Y48: 46119.462

Sheet resultados_finais - Copia (4)
A1: run_id | B1: arquivo_instancia | C1: ninst | D1: tem_janelas | E1: heuristica_retirada | F1: tamanho_clientes | G1: nos_rede | H1: veiculos | I1: capacidade | J1: tabu | K1: tipo_geracao | L1: tempo_exato | M1: tempo_bp | N1: fo_exato | O1: fo_bp | P1: gap_pct | Q1: igual_exato | R1: nos_bp | S1: colunas_bp | T1: seq_exato | U1: seq_bp | V1: timestamp
A2: tam25_cap200_tabu0_inst0_cons0 | B2: instancias/r101,txt | C2: 0 | D2: 0 | E2: 0 | F2: 25 | G2: 27 | H2: 8 | I2: 200 | J2: 0 | K2: PD | L2: 0.7642 | M2: 67.9489 | N2: 618.3299 | O2: 618.3299 | P2: 0 | Q2: 1 | R2: 1 | S2: 872 | T2: V0: [0,12,9,20,1,26] ; V1: [0,11,19,10,26] ; V2: [0,18,26] ; V3: [0,23,22,4,26] ; V4: [0,7,8,17,26] ; V5: [0,5,16,6,26] ; V6: [0,2,21,3,24,25,26] ; V7: [0,14,15,13,26] | U2: V0: [0,23,22,4,25,26] ; V1: [0,5,16,6,26] ; V2: [0,12,9,20,1,26] ; V3: [0,2,21,3,24,26] ; V4: [0,11,19,10,26] ; V5: [0,7,8,17,26] ; V6: [0,18,26] ; V7: [0,14,15,13,26] | V2: 46108.866 | X2: Analise | Y2: GAP
A3: tam25_cap200_tabu0_inst0_cons1 | B3: instancias/r101,txt | C3: 0 | D3: 0 | E3: 1 | F3: 25 | G3: 27 | H3: 8 | I3: 200 | J3: 0 | K3: PD | L3: 0.7642 | M3: 20.2125 | N3: 618.3299 | O3: 618.3299 | P3: 0 | Q3: 1 | R3: 1 | S3: 992 | T3: V0: [0,12,9,20,1,26] ; V1: [0,11,19,10,26] ; V2: [0,18,26] ; V3: [0,23,22,4,26] ; V4: [0,7,8,17,26] ; V5: [0,5,16,6,26] ; V6: [0,2,21,3,24,25,26] ; V7: [0,14,15,13,26] | U3: V0: [0,2,21,3,24,25,26] ; V1: [0,12,9,20,1,26] ; V2: [0,11,19,10,26] ; V3: [0,23,22,4,26] ; V4: [0,18,26] ; V5: [0,5,16,6,26] ; V6: [0,14,15,13,26] ; V7: [0,7,8,17,26] | V3: 46108.866 | X3: heuristica | Y3: MÁXIMO | Z3: inst | AA3: MÍNIMO | AB3: inst | AC3: MÉDIA
A4: tam25_cap200_tabu0_inst0_cons2 | B4: instancias/r101,txt | C4: 0 | D4: 0 | E4: 2 | F4: 25 | G4: 27 | H4: 8 | I4: 200 | J4: 0 | K4: PD | L4: 0.7642 | M4: 23.3106 | N4: 618.3299 | O4: 618.3299 | P4: 0 | Q4: 1 | R4: 1 | S4: 1208 | T4: V0: [0,12,9,20,1,26] ; V1: [0,11,19,10,26] ; V2: [0,18,26] ; V3: [0,23,22,4,26] ; V4: [0,7,8,17,26] ; V5: [0,5,16,6,26] ; V6: [0,2,21,3,24,25,26] ; V7: [0,14,15,13,26] | U4: V0: [0,12,9,20,1,26] ; V1: [0,23,22,4,26] ; V2: [0,11,19,10,26] ; V3: [0,7,8,17,26] ; V4: [0,14,15,13,26] ; V5: [0,18,26] ; V6: [0,5,16,6,26] ; V7: [0,2,21,3,24,25,26] | V4: 46108.866 | X4: 0 | Y4: 9.7493 | Z4: instancias/c202,txt | AA4: 0 | AB4: instancias/r101,txt | AC4: 2.68375
A5: tam25_cap200_tabu0_inst0_cons3 | B5: instancias/r101,txt | C5: 0 | D5: 0 | E5: 3 | F5: 25 | G5: 27 | H5: 8 | I5: 200 | J5: 0 | K5: PD | L5: 0.7642 | M5: 2.2683 | N5: 618.3299 | O5: 630.3804 | P5: 1.9489 | Q5: 0 | R5: 1 | S5: 952 | T5: V0: [0,12,9,20,1,26] ; V1: [0,11,19,10,26] ; V2: [0,18,26] ; V3: [0,23,22,4,26] ; V4: [0,7,8,17,26] ; V5: [0,5,16,6,26] ; V6: [0,2,21,3,24,25,26] ; V7: [0,14,15,13,26] | U5: V0: [0,12,9,20,26] ; V1: [0,7,8,26] ; V2: [0,18,26] ; V3: [0,14,15,6,13,26] ; V4: [0,5,16,17,26] ; V5: [0,23,22,4,26] ; V6: [0,11,19,10,1,26] ; V7: [0,2,21,3,24,25,26] | V5: 46108.866 | W5: inserção com melhoria | X5: 1 | Y5: 17.725 | Z5: instancias/c202,txt | AA5: 0 | AB5: instancias/r101,txt | AC5: 2.88909
A6: tam25_cap200_tabu0_inst0_cons22 | B6: instancias/r101,txt | C6: 0 | D6: 0 | E6: 22 | F6: 25 | G6: 27 | H6: 8 | I6: 200 | J6: 0 | K6: PD | L6: 0.7642 | M6: 99.9047 | N6: 618.3299 | O6: 618.3299 | P6: 0 | Q6: 1 | R6: 1 | S6: 480 | T6: V0: [0,12,9,20,1,26] ; V1: [0,11,19,10,26] ; V2: [0,18,26] ; V3: [0,23,22,4,26] ; V4: [0,7,8,17,26] ; V5: [0,5,16,6,26] ; V6: [0,2,21,3,24,25,26] ; V7: [0,14,15,13,26] | U6: V0: [0,5,16,6,26] ; V1: [0,14,15,13,26] ; V2: [0,12,9,20,1,26] ; V3: [0,7,8,17,26] ; V4: [0,18,26] ; V5: [0,11,19,10,26] ; V6: [0,2,21,3,24,26] ; V7: [0,23,22,4,25,26] | V6: 46108.867 | W6: vns_ com acrescimo | X6: 2 | Y6: 4.95 | Z6: instancias/c202,txt | AA6: 0 | AB6: instancias/r101,txt | AC6: 0.86775
A7: tam25_cap200_tabu0_inst0_cons0 | B7: instancias/r102,txt | C7: 0 | D7: 0 | E7: 0 | F7: 25 | G7: 27 | H7: 7 | I7: 200 | J7: 0 | K7: PD | L7: 1201.1008 | M7: 2666.8414 | N7: 548.1078 | O7: 548.1078 | P7: 0 | Q7: 1 | R7: 713 | S7: 2793 | T7: V0: [0,14,16,6,13,26] ; V1: [0,3,9,20,1,26] ; V2: [0,7,11,19,10,26] ; V3: [0,2,15,22,4,25,26] ; V4: [0,18,26] ; V5: [0,8,17,5,26] ; V6: [0,21,23,24,12,26] | U7: V0: [0,14,16,6,13,26] ; V1: [0,7,11,19,10,26] ; V2: [0,21,23,24,12,26] ; V3: [0,2,15,22,4,25,26] ; V4: [0,8,17,5,26] ; V5: [0,3,9,20,1,26] ; V6: [0,18,26] | V7: 46108.912 | W7: sem pd | X7: 3 | Y7: 8.4445 | Z7: instancias/c201,txt | AA7: 0 | AB7: instancias/r101,txt | AC7: 3.6711182
A8: tam25_cap200_tabu0_inst0_cons1 | B8: instancias/r102,txt | C8: 0 | D8: 0 | E8: 1 | F8: 25 | G8: 27 | H8: 7 | I8: 200 | J8: 0 | K8: PD | L8: 1201.1008 | M8: 2980.3445 | N8: 548.1078 | O8: 548.1078 | P8: 0 | Q8: 1 | R8: 2017 | S8: 2289 | T8: V0: [0,14,16,6,13,26] ; V1: [0,3,9,20,1,26] ; V2: [0,7,11,19,10,26] ; V3: [0,2,15,22,4,25,26] ; V4: [0,18,26] ; V5: [0,8,17,5,26] ; V6: [0,21,23,24,12,26] | U8: V0: [0,21,23,24,12,26] ; V1: [0,2,15,22,4,25,26] ; V2: [0,3,9,20,1,26] ; V3: [0,8,17,5,26] ; V4: [0,18,26] ; V5: [0,7,11,19,10,26] ; V6: [0,14,16,6,13,26] | V8: 46108.947 | W8: apenas pd | X8: 22 | Y8: 25.9309 | Z8: instancias/r102,txt | AA8: 0 | AB8: instancias/r101,txt | AC8: 5.2196
A9: tam25_cap200_tabu0_inst0_cons2 | B9: instancias/r102,txt | C9: 0 | D9: 0 | E9: 2 | F9: 25 | G9: 27 | H9: 7 | I9: 200 | J9: 0 | K9: PD | L9: 1201.1008 | M9: 2381.7852 | N9: 548.1078 | O9: 548.1078 | P9: 0 | Q9: 1 | R9: 1435 | S9: 2268 | T9: V0: [0,14,16,6,13,26] ; V1: [0,3,9,20,1,26] ; V2: [0,7,11,19,10,26] ; V3: [0,2,15,22,4,25,26] ; V4: [0,18,26] ; V5: [0,8,17,5,26] ; V6: [0,21,23,24,12,26] | U9: V0: [0,8,17,5,26] ; V1: [0,3,9,20,1,26] ; V2: [0,21,23,24,12,26] ; V3: [0,18,26] ; V4: [0,7,11,19,10,26] ; V5: [0,14,16,6,13,26] ; V6: [0,2,15,22,4,25,26] | V9: 46108.974 | W9: todas | X9: 10 | Y9: 3.3816 | Z9: instancias/c109,txt | AA9: 0 | AB9: instancias/r101,txt | AC9: 0.2570625
A10: tam25_cap200_tabu0_inst0_cons3 | B10: instancias/r102,txt | C10: 0 | D10: 0 | E10: 3 | F10: 25 | G10: 27 | H10: 7 | I10: 200 | J10: 0 | K10: PD | L10: 1201.1008 | M10: 106.3065 | N10: 548.1078 | O10: 551.622 | P10: 0.6411 | Q10: 0 | R10: 211 | S10: 2485 | T10: V0: [0,14,16,6,13,26] ; V1: [0,3,9,20,1,26] ; V2: [0,7,11,19,10,26] ; V3: [0,2,15,22,4,25,26] ; V4: [0,18,26] ; V5: [0,8,17,5,26] ; V6: [0,21,23,24,12,26] | U10: V0: [0,2,15,22,4,25,12,26] ; V1: [0,3,9,20,1,26] ; V2: [0,18,6,13,26] ; V3: [0,8,26] ; V4: [0,7,11,19,10,26] ; V5: [0,14,16,17,5,26] ; V6: [0,21,23,24,26] | V10: 46108.976 | AA10: 0
A11: tam25_cap200_tabu0_inst0_cons22 | B11: instancias/r102,txt | C11: 0 | D11: 0 | E11: 22 | F11: 25 | G11: 27 | H11: 7 | I11: 200 | J11: 0 | K11: PD | L11: 1201.1008 | M11: 3600.2436 | N11: 548.1078 | O11: 690.2369 | P11: 25.9309 | Q11: 0 | R11: 1878 | S11: 714 | T11: V0: [0,14,16,6,13,26] ; V1: [0,3,9,20,1,26] ; V2: [0,7,11,19,10,26] ; V3: [0,2,15,22,4,25,26] ; V4: [0,18,26] ; V5: [0,8,17,5,26] ; V6: [0,21,23,24,12,26] | U11: V0: [0,21,23,24,12,26] ; V1: [0,2,15,22,4,25,26] ; V2: [0,18,6,13,26] ; V3: [0,8,10,26] ; V4: [0,16,17,26] ; V5: [0,5,11,19,3,26] ; V6: [0,14,9,20,1,7,26] | V11: 46109.017
A12: tam25_cap200_tabu0_inst0_cons0 | B12: instancias/r103,txt | C12: 0 | D12: 0 | E12: 0 | F12: 25 | G12: 27 | H12: 5 | I12: 200 | J12: 0 | K12: PD | L12: 1201.3643 | M12: 142.071 | N12: 468.2479 | O12: 455.6982 | P12: -2.6801 | Q12: 0 | R12: 1 | S12: 1375 | T12: V0: [0,7,19,11,10,26] ; V1: [0,2,21,23,22,4,25,26] ; V2: [0,14,15,6,13,26] ; V3: [0,1,20,9,3,24,12,26] ; V4: [0,18,8,17,16,5,26] | U12: V0: [0,7,19,11,8,18,26] ; V1: [0,12,24,3,9,10,20,1,26] ; V2: [0,2,15,14,16,17,5,26] ; V3: [0,6,13,26] ; V4: [0,21,23,22,4,25,26] | V12: 46109.033 | X12: Analise | Y12: TIME
A13: tam25_cap200_tabu0_inst0_cons1 | B13: instancias/r103,txt | C13: 0 | D13: 0 | E13: 1 | F13: 25 | G13: 27 | H13: 5 | I13: 200 | J13: 0 | K13: PD | L13: 1201.3643 | M13: 109.9558 | N13: 468.2479 | O13: 455.6982 | P13: -2.6801 | Q13: 0 | R13: 1 | S13: 1450 | T13: V0: [0,7,19,11,10,26] ; V1: [0,2,21,23,22,4,25,26] ; V2: [0,14,15,6,13,26] ; V3: [0,1,20,9,3,24,12,26] ; V4: [0,18,8,17,16,5,26] | U13: V0: [0,2,15,14,16,17,5,26] ; V1: [0,7,19,11,8,18,26] ; V2: [0,21,23,22,4,25,26] ; V3: [0,6,13,26] ; V4: [0,12,24,3,9,10,20,1,26] | V13: 46109.034 | X13: heuristica | Y13: MÁXIMO | Z13: inst | AA13: MÍNIMO | AB13: inst | AC13: MÉDIA
A14: tam25_cap200_tabu0_inst0_cons2 | B14: instancias/r103,txt | C14: 0 | D14: 0 | E14: 2 | F14: 25 | G14: 27 | H14: 5 | I14: 200 | J14: 0 | K14: PD | L14: 1201.3643 | M14: 111.5374 | N14: 468.2479 | O14: 455.6982 | P14: -2.6801 | Q14: 0 | R14: 1 | S14: 1380 | T14: V0: [0,7,19,11,10,26] ; V1: [0,2,21,23,22,4,25,26] ; V2: [0,14,15,6,13,26] ; V3: [0,1,20,9,3,24,12,26] ; V4: [0,18,8,17,16,5,26] | U14: V0: [0,12,24,3,9,10,20,1,26] ; V1: [0,21,23,22,4,25,26] ; V2: [0,2,15,14,16,17,5,26] ; V3: [0,6,13,26] ; V4: [0,7,19,11,8,18,26] | V14: 46109.035 | X14: 0 | Y14: 3999.3001 | Z14: instancias/c202,txt | AA14: 67.9489 | AC14: 1577.3656
A15: tam25_cap200_tabu0_inst0_cons3 | B15: instancias/r103,txt | C15: 0 | D15: 0 | E15: 3 | F15: 25 | G15: 27 | H15: 5 | I15: 200 | J15: 0 | K15: PD | L15: 1201.3643 | M15: 164.3832 | N15: 468.2479 | O15: 468.1968 | P15: -0.0109 | Q15: 0 | R15: 379 | S15: 2445 | T15: V0: [0,7,19,11,10,26] ; V1: [0,2,21,23,22,4,25,26] ; V2: [0,14,15,6,13,26] ; V3: [0,1,20,9,3,24,12,26] ; V4: [0,18,8,17,16,5,26] | U15: V0: [0,24,3,9,10,20,1,26] ; V1: [0,6,13,26] ; V2: [0,15,14,16,17,5,26] ; V3: [0,7,19,11,8,18,26] ; V4: [0,2,21,23,22,4,25,12,26] | V15: 46109.037 | X15: 1 | Y15: 3786.1477 | Z15: instancias/c203,txt | AA15: 20.2125 | AC15: 1251.4237
A16: tam25_cap200_tabu0_inst0_cons22 | B16: instancias/r103,txt | C16: 0 | D16: 0 | E16: 22 | F16: 25 | G16: 27 | H16: 5 | I16: 200 | J16: 0 | K16: PD | L16: 1201.3643 | M16: 447.5025 | N16: 468.2479 | O16: 455.6982 | P16: -2.6801 | Q16: 0 | R16: 1 | S16: 645 | T16: V0: [0,7,19,11,10,26] ; V1: [0,2,21,23,22,4,25,26] ; V2: [0,14,15,6,13,26] ; V3: [0,1,20,9,3,24,12,26] ; V4: [0,18,8,17,16,5,26] | U16: V0: [0,21,23,22,4,25,26] ; V1: [0,2,15,14,16,17,5,26] ; V2: [0,6,13,26] ; V3: [0,7,19,11,8,18,26] ; V4: [0,12,24,3,9,10,20,1,26] | V16: 46109.042 | X16: 2 | Y16: 4212.7162 | Z16: instancias/c203,txt | AA16: 23.3106 | AC16: 1214.4434
A17: tam25_cap200_tabu0_inst0_cons0 | B17: instancias/r104,txt | C17: 0 | D17: 0 | E17: 0 | F17: 25 | G17: 27 | H17: 4 | I17: 200 | J17: 0 | K17: PD | L17: 1201.5134 | M17: 119.9116 | N17: 453.6869 | O17: 417.9612 | P17: -7.8745 | Q17: 0 | R17: 1 | S17: 1040 | T17: V0: [0,15,16,14,13,26] ; V1: [0,21,22,23,4,2,6,26] ; V2: [0,7,19,11,8,17,5,18,26] ; V3: [0,1,10,20,9,3,24,25,12,26] | U17: V0: [0,7,19,11,8,18,6,13,26] ; V1: [0,1,10,20,9,3,24,12,26] ; V2: [0,2,15,14,16,17,5,26] ; V3: [0,21,22,23,4,25,26] | V17: 46109.058 | X17: 3 | Y17: 3633.8025 | Z17: instancias/c202,txt | AA17: 2.2683 | AC17: 814.73283
A18: tam25_cap200_tabu0_inst0_cons1 | B18: instancias/r104,txt | C18: 0 | D18: 0 | E18: 1 | F18: 25 | G18: 27 | H18: 4 | I18: 200 | J18: 0 | K18: PD | L18: 1201.5134 | M18: 150.0521 | N18: 453.6869 | O18: 417.9612 | P18: -7.8745 | Q18: 0 | R18: 15 | S18: 1752 | T18: V0: [0,15,16,14,13,26] ; V1: [0,21,22,23,4,2,6,26] ; V2: [0,7,19,11,8,17,5,18,26] ; V3: [0,1,10,20,9,3,24,25,12,26] | U18: V0: [0,21,22,23,4,25,26] ; V1: [0,2,15,14,16,17,5,26] ; V2: [0,7,19,11,8,18,6,13,26] ; V3: [0,1,10,20,9,3,24,12,26] | V18: 46109.06 | X18: 22 | Y18: 4554.6505 | Z18: instancias/c203,txt | AA18: 99.9047 | AC18: 2195.5316
A19: tam25_cap200_tabu0_inst0_cons2 | B19: instancias/r104,txt | C19: 0 | D19: 0 | E19: 2 | F19: 25 | G19: 27 | H19: 4 | I19: 200 | J19: 0 | K19: PD | L19: 1201.5134 | M19: 86.7017 | N19: 453.6869 | O19: 417.9612 | P19: -7.8745 | Q19: 0 | R19: 1 | S19: 1384 | T19: V0: [0,15,16,14,13,26] ; V1: [0,21,22,23,4,2,6,26] ; V2: [0,7,19,11,8,17,5,18,26] ; V3: [0,1,10,20,9,3,24,25,12,26] | U19: V0: [0,2,15,14,16,17,5,26] ; V1: [0,21,22,23,4,25,26] ; V2: [0,1,10,20,9,3,24,12,26] ; V3: [0,7,19,11,8,18,6,13,26] | V19: 46109.06 | X19: 10 | Y19: 3346.43 | Z19: instancias/r112,txt | AA19: 25.3171 | AC19: 545.35546
A20: tam25_cap200_tabu0_inst0_cons3 | B20: instancias/r104,txt | C20: 0 | D20: 0 | E20: 3 | F20: 25 | G20: 27 | H20: 4 | I20: 200 | J20: 0 | K20: PD | L20: 1201.5134 | M20: 18.8865 | N20: 453.6869 | O20: 427.2213 | P20: -5.8334 | Q20: 0 | R20: 1 | S20: 1744 | T20: V0: [0,15,16,14,13,26] ; V1: [0,21,22,23,4,2,6,26] ; V2: [0,7,19,11,8,17,5,18,26] ; V3: [0,1,10,20,9,3,24,25,12,26] | U20: V0: [0,1,10,20,9,3,24,25,12,26] ; V1: [0,7,19,11,8,17,16,5,18,26] ; V2: [0,21,22,23,4,26] ; V3: [0,6,14,15,2,13,26] | V20: 46109.06
A21: tam25_cap200_tabu0_inst0_cons22 | B21: instancias/r104,txt | C21: 0 | D21: 0 | E21: 22 | F21: 25 | G21: 27 | H21: 4 | I21: 200 | J21: 0 | K21: PD | L21: 1201.5134 | M21: 392.8058 | N21: 453.6869 | O21: 420.6334 | P21: -7.2855 | Q21: 0 | R21: 1 | S21: 500 | T21: V0: [0,15,16,14,13,26] ; V1: [0,21,22,23,4,2,6,26] ; V2: [0,7,19,11,8,17,5,18,26] ; V3: [0,1,10,20,9,3,24,25,12,26] | U21: V0: [0,7,19,11,8,18,6,13,26] ; V1: [0,2,15,14,16,17,5,26] ; V2: [0,21,22,23,4,25,12,26] ; V3: [0,24,3,9,20,10,1,26] | V21: 46109.065
A22: tam25_cap200_tabu0_inst0_cons0 | B22: instancias/r105,txt | C22: 0 | D22: 0 | E22: 0 | F22: 25 | G22: 27 | H22: 6 | I22: 200 | J22: 0 | K22: PD | L22: 17.8249 | M22: 90.9081 | N22: 531.5386 | O22: 531.5386 | P22: 0 | Q22: 1 | R22: 1 | S22: 828 | T22: V0: [0,5,14,16,6,26] ; V1: [0,12,9,3,24,25,26] ; V2: [0,2,15,13,26] ; V3: [0,21,23,22,4,26] ; V4: [0,7,18,8,17,26] ; V5: [0,19,11,10,20,1,26] | U22: V0: [0,5,14,16,6,26] ; V1: [0,19,11,10,20,1,26] ; V2: [0,7,18,8,17,26] ; V3: [0,12,9,3,24,26] ; V4: [0,2,15,13,26] ; V5: [0,21,23,22,4,25,26] | V22: 46109.067
A23: tam25_cap200_tabu0_inst0_cons1 | B23: instancias/r105,txt | C23: 0 | D23: 0 | E23: 1 | F23: 25 | G23: 27 | H23: 6 | I23: 200 | J23: 0 | K23: PD | L23: 17.8249 | M23: 56.1524 | N23: 531.5386 | O23: 531.5386 | P23: 0 | Q23: 1 | R23: 1 | S23: 1134 | T23: V0: [0,5,14,16,6,26] ; V1: [0,12,9,3,24,25,26] ; V2: [0,2,15,13,26] ; V3: [0,21,23,22,4,26] ; V4: [0,7,18,8,17,26] ; V5: [0,19,11,10,20,1,26] | U23: V0: [0,19,11,10,20,1,26] ; V1: [0,12,9,3,24,25,26] ; V2: [0,5,14,16,6,26] ; V3: [0,7,18,8,17,26] ; V4: [0,2,15,13,26] ; V5: [0,21,23,22,4,26] | V23: 46109.067
A24: tam25_cap200_tabu0_inst0_cons2 | B24: instancias/r105,txt | C24: 0 | D24: 0 | E24: 2 | F24: 25 | G24: 27 | H24: 6 | I24: 200 | J24: 0 | K24: PD | L24: 17.8249 | M24: 57.6008 | N24: 531.5386 | O24: 531.5386 | P24: 0 | Q24: 1 | R24: 1 | S24: 1242 | T24: V0: [0,5,14,16,6,26] ; V1: [0,12,9,3,24,25,26] ; V2: [0,2,15,13,26] ; V3: [0,21,23,22,4,26] ; V4: [0,7,18,8,17,26] ; V5: [0,19,11,10,20,1,26] | U24: V0: [0,21,23,22,4,25,26] ; V1: [0,19,11,10,20,1,26] ; V2: [0,7,18,8,17,26] ; V3: [0,5,14,16,6,26] ; V4: [0,12,9,3,24,26] ; V5: [0,2,15,13,26] | V24: 46109.068
A25: tam25_cap200_tabu0_inst0_cons3 | B25: instancias/r105,txt | C25: 0 | D25: 0 | E25: 3 | F25: 25 | G25: 27 | H25: 6 | I25: 200 | J25: 0 | K25: PD | L25: 17.8249 | M25: 22.6073 | N25: 531.5386 | O25: 537.5166 | P25: 1.1247 | Q25: 0 | R25: 65 | S25: 1452 | T25: V0: [0,5,14,16,6,26] ; V1: [0,12,9,3,24,25,26] ; V2: [0,2,15,13,26] ; V3: [0,21,23,22,4,26] ; V4: [0,7,18,8,17,26] ; V5: [0,19,11,10,20,1,26] | U25: V0: [0,18,6,26] ; V1: [0,21,23,22,4,26] ; V2: [0,12,9,3,24,25,26] ; V3: [0,5,14,16,8,17,26] ; V4: [0,11,19,7,10,20,1,26] ; V5: [0,2,15,13,26] | V25: 46109.068
A26: tam25_cap200_tabu0_inst0_cons22 | B26: instancias/r105,txt | C26: 0 | D26: 0 | E26: 22 | F26: 25 | G26: 27 | H26: 6 | I26: 200 | J26: 0 | K26: PD | L26: 17.8249 | M26: 210.8627 | N26: 531.5386 | O26: 531.5386 | P26: 0 | Q26: 1 | R26: 1 | S26: 492 | T26: V0: [0,5,14,16,6,26] ; V1: [0,12,9,3,24,25,26] ; V2: [0,2,15,13,26] ; V3: [0,21,23,22,4,26] ; V4: [0,7,18,8,17,26] ; V5: [0,19,11,10,20,1,26] | U26: V0: [0,2,15,13,26] ; V1: [0,21,23,22,4,26] ; V2: [0,12,9,3,24,25,26] ; V3: [0,19,11,10,20,1,26] ; V4: [0,7,18,8,17,26] ; V5: [0,5,14,16,6,26] | V26: 46109.07
A27: tam25_cap200_tabu0_inst0_cons0 | B27: instancias/r106,txt | C27: 0 | D27: 0 | E27: 0 | F27: 25 | G27: 27 | H27: 5 | I27: 200 | J27: 0 | K27: PD | L27: 1092.5516 | M27: 1481.3308 | N27: 466.4802 | O27: 470.5235 | P27: 0.8668 | Q27: 0 | R27: 307 | S27: 2765 | T27: V0: [0,2,15,23,22,4,25,21,26] ; V1: [0,14,16,6,13,26] ; V2: [0,7,19,11,10,26] ; V3: [0,18,8,17,5,26] ; V4: [0,1,9,20,3,24,12,26] | U27: V0: [0,1,9,20,3,24,26] ; V1: [0,14,16,6,13,26] ; V2: [0,18,8,17,5,26] ; V3: [0,2,15,23,22,21,4,25,12,26] ; V4: [0,7,19,11,10,26] | V27: 46109.1
A28: tam25_cap200_tabu0_inst0_cons1 | B28: instancias/r106,txt | C28: 0 | D28: 0 | E28: 1 | F28: 25 | G28: 27 | H28: 5 | I28: 200 | J28: 0 | K28: PD | L28: 1092.5516 | M28: 809.2501 | N28: 466.4802 | O28: 466.4802 | P28: 0 | Q28: 1 | R28: 137 | S28: 2280 | T28: V0: [0,2,15,23,22,4,25,21,26] ; V1: [0,14,16,6,13,26] ; V2: [0,7,19,11,10,26] ; V3: [0,18,8,17,5,26] ; V4: [0,1,9,20,3,24,12,26] | U28: V0: [0,7,19,11,10,26] ; V1: [0,2,15,23,22,4,25,21,26] ; V2: [0,18,8,17,5,26] ; V3: [0,14,16,6,13,26] ; V4: [0,1,9,20,3,24,12,26] | V28: 46109.11
A29: tam25_cap200_tabu0_inst0_cons2 | B29: instancias/r106,txt | C29: 0 | D29: 0 | E29: 2 | F29: 25 | G29: 27 | H29: 5 | I29: 200 | J29: 0 | K29: PD | L29: 1092.5516 | M29: 875.5637 | N29: 466.4802 | O29: 466.4802 | P29: 0 | Q29: 1 | R29: 153 | S29: 2390 | T29: V0: [0,2,15,23,22,4,25,21,26] ; V1: [0,14,16,6,13,26] ; V2: [0,7,19,11,10,26] ; V3: [0,18,8,17,5,26] ; V4: [0,1,9,20,3,24,12,26] | U29: V0: [0,7,19,11,10,26] ; V1: [0,2,15,23,22,4,25,21,26] ; V2: [0,14,16,6,13,26] ; V3: [0,1,9,20,3,24,12,26] ; V4: [0,18,8,17,5,26] | V29: 46109.119
A30: tam25_cap200_tabu0_inst0_cons3 | B30: instancias/r106,txt | C30: 0 | D30: 0 | E30: 3 | F30: 25 | G30: 27 | H30: 5 | I30: 200 | J30: 0 | K30: PD | L30: 1092.5516 | M30: 2234.3161 | N30: 466.4802 | O30: 501.4534 | P30: 7.4973 | Q30: 0 | R30: 16147 | S30: 6465 | T30: V0: [0,2,15,23,22,4,25,21,26] ; V1: [0,14,16,6,13,26] ; V2: [0,7,19,11,10,26] ; V3: [0,18,8,17,5,26] ; V4: [0,1,9,20,3,24,12,26] | U30: V0: [0,19,11,10,20,26] ; V1: [0,2,14,16,5,6,13,26] ; V2: [0,7,18,8,17,26] ; V3: [0,21,15,23,22,4,25,12,26] ; V4: [0,1,9,3,24,26] | V30: 46109.146
A31: tam25_cap200_tabu0_inst0_cons22 | B31: instancias/r106,txt | C31: 0 | D31: 0 | E31: 22 | F31: 25 | G31: 27 | H31: 5 | I31: 200 | J31: 0 | K31: PD | L31: 1092.5516 | M31: 3602.4569 | N31: 466.4802 | O31: -1 | R31: 0 | S31: 0 | T31: V0: [0,2,15,23,22,4,25,21,26] ; V1: [0,14,16,6,13,26] ; V2: [0,7,19,11,10,26] ; V3: [0,18,8,17,5,26] ; V4: [0,1,9,20,3,24,12,26] | U31: SEM_SEQUENCIA_BP | V31: 46109.188
A32: tam25_cap200_tabu0_inst0_cons0 | B32: instancias/r107,txt | C32: 0 | D32: 0 | E32: 0 | F32: 25 | G32: 27 | H32: 4 | I32: 200 | J32: 0 | K32: PD | L32: 1201.3898 | M32: 169.633 | N32: 429.2004 | O32: 425.2685 | P32: -0.9161 | Q32: 0 | R32: 1 | S32: 1156 | T32: V0: [0,6,16,14,13,26] ; V1: [0,18,7,11,19,8,17,5,26] ; V2: [0,2,15,23,22,4,25,21,26] ; V3: [0,12,24,3,9,20,10,1,26] | U32: V0: [0,18,7,11,19,8,17,16,5,26] ; V1: [0,21,23,22,4,25,24,26] ; V2: [0,12,3,9,20,10,1,26] ; V3: [0,2,15,14,6,13,26] | V32: 46109.203
A33: tam25_cap200_tabu0_inst0_cons1 | B33: instancias/r107,txt | C33: 0 | D33: 0 | E33: 1 | F33: 25 | G33: 27 | H33: 4 | I33: 200 | J33: 0 | K33: PD | L33: 1201.3898 | M33: 183.1797 | N33: 429.2004 | O33: 425.2685 | P33: -0.9161 | Q33: 0 | R33: 1 | S33: 1808 | T33: V0: [0,6,16,14,13,26] ; V1: [0,18,7,11,19,8,17,5,26] ; V2: [0,2,15,23,22,4,25,21,26] ; V3: [0,12,24,3,9,20,10,1,26] | U33: V0: [0,12,3,9,20,10,1,26] ; V1: [0,18,7,11,19,8,17,16,5,26] ; V2: [0,21,23,22,4,25,24,26] ; V3: [0,2,15,14,6,13,26] | V33: 46109.206
