Workbook

Sheet PRICING25
A1: run_id | B1: arquivo_instancia | C1: ninst | D1: tem_janelas | E1: heuristica_retirada | F1: tamanho_clientes | G1: nos_rede | H1: veiculos | I1: capacidade | J1: tabu | K1: tipo_geracao | L1: tempo_exato | M1: tempo_bp | N1: fo_exato | O1: fo_bp | P1: gap_pct | Q1: igual_exato | R1: nos_bp | S1: colunas_bp | T1: seq_exato | U1: seq_bp | V1: timestamp
A2: tam25_cap200_tabu0_inst0_cons0 | B2: instancias/r101,txt | C2: 0 | D2: 0 | E2: 0 | F2: 25 | G2: 27 | H2: 8 | I2: 200 | J2: 0 | K2: PD | L2: 0.7642 | M2: 67.9489 | N2: 618.3299 | O2: 618.3299 | P2: =(O2-N2)/O2 -> 0 | Q2: 1 | R2: 1 | S2: 872 | T2: V0: [0,12,9,20,1,26] ; V1: [0,11,19,10,26] ; V2: [0,18,26] ; V3: [0,23,22,4,26] ; V4: [0,7,8,17,26] ; V5: [0,5,16,6,26] ; V6: [0,2,21,3,24,25,26] ; V7: [0,14,15,13,26] | U2: V0: [0,23,22,4,25,26] ; V1: [0,5,16,6,26] ; V2: [0,12,9,20,1,26] ; V3: [0,2,21,3,24,26] ; V4: [0,11,19,10,26] ; V5: [0,7,8,17,26] ; V6: [0,18,26] ; V7: [0,14,15,13,26] | V2: 46108.866 | X2: Analise | Y2: GAP
A3: tam25_cap200_tabu0_inst0_cons1 | B3: instancias/r101,txt | C3: 0 | D3: 0 | E3: 1 | F3: 25 | G3: 27 | H3: 8 | I3: 200 | J3: 0 | K3: PD | L3: 0.7642 | M3: 20.2125 | N3: 618.3299 | O3: 618.3299 | P3: =(O3-N3)/O3 -> 0 | Q3: 1 | R3: 1 | S3: 992 | T3: V0: [0,12,9,20,1,26] ; V1: [0,11,19,10,26] ; V2: [0,18,26] ; V3: [0,23,22,4,26] ; V4: [0,7,8,17,26] ; V5: [0,5,16,6,26] ; V6: [0,2,21,3,24,25,26] ; V7: [0,14,15,13,26] | U3: V0: [0,2,21,3,24,25,26] ; V1: [0,12,9,20,1,26] ; V2: [0,11,19,10,26] ; V3: [0,23,22,4,26] ; V4: [0,18,26] ; V5: [0,5,16,6,26] ; V6: [0,14,15,13,26] ; V7: [0,7,8,17,26] | V3: 46108.866 | X3: heuristica | Y3: MÁXIMO | Z3: inst | AA3: MÍNIMO | AB3: inst | AC3: MÉDIA | AF3: Análise feita para
A4: tam25_cap200_tabu0_inst0_cons2 | B4: instancias/r101,txt | C4: 0 | D4: 0 | E4: 2 | F4: 25 | G4: 27 | H4: 8 | I4: 200 | J4: 0 | K4: PD | L4: 0.7642 | M4: 23.3106 | N4: 618.3299 | O4: 618.3299 | P4: =(O4-N4)/O4 -> 0 | Q4: 1 | R4: 1 | S4: 1208 | T4: V0: [0,12,9,20,1,26] ; V1: [0,11,19,10,26] ; V2: [0,18,26] ; V3: [0,23,22,4,26] ; V4: [0,7,8,17,26] ; V5: [0,5,16,6,26] ; V6: [0,2,21,3,24,25,26] ; V7: [0,14,15,13,26] | U4: V0: [0,12,9,20,1,26] ; V1: [0,23,22,4,26] ; V2: [0,11,19,10,26] ; V3: [0,7,8,17,26] ; V4: [0,14,15,13,26] ; V5: [0,18,26] ; V6: [0,5,16,6,26] ; V7: [0,2,21,3,24,25,26] | V4: 46108.866 | X4: 0 | Y4: =_xlfn.MAXIFS($P:$P,$E:$E,X4) -> 0.088832764 | Z4: instancias/c202,txt | AA4: =_xlfn.MINIFS($P:$P,$E:$E,X4) -> 0 | AB4: instancias/r101,txt | AC4: =AVERAGEIFS($P:$P,$E:$E,X4) -> 0.018098658
A5: tam25_cap200_tabu0_inst0_cons3 | B5: instancias/r101,txt | C5: 0 | D5: 0 | E5: 3 | F5: 25 | G5: 27 | H5: 8 | I5: 200 | J5: 0 | K5: PD | L5: 0.7642 | M5: 2.2683 | N5: 618.3299 | O5: 630.3804 | P5: =(O5-N5)/O5 -> 0.019116235 | Q5: 0 | R5: 1 | S5: 952 | T5: V0: [0,12,9,20,1,26] ; V1: [0,11,19,10,26] ; V2: [0,18,26] ; V3: [0,23,22,4,26] ; V4: [0,7,8,17,26] ; V5: [0,5,16,6,26] ; V6: [0,2,21,3,24,25,26] ; V7: [0,14,15,13,26] | U5: V0: [0,12,9,20,26] ; V1: [0,7,8,26] ; V2: [0,18,26] ; V3: [0,14,15,6,13,26] ; V4: [0,5,16,17,26] ; V5: [0,23,22,4,26] ; V6: [0,11,19,10,1,26] ; V7: [0,2,21,3,24,25,26] | V5: 46108.866 | W5: inserção com melhoria | X5: 1 | Y5: =_xlfn.MAXIFS($P:$P,$E:$E,X5) -> 0.15056297 | Z5: instancias/c202,txt | AA5: =_xlfn.MINIFS($P:$P,$E:$E,X5) -> 0 | AB5: instancias/r101,txt | AC5: =AVERAGEIFS($P:$P,$E:$E,X5) -> 0.018266751
A6: tam25_cap200_tabu0_inst0_cons22 | B6: instancias/r101,txt | C6: 0 | D6: 0 | E6: 22 | F6: 25 | G6: 27 | H6: 8 | I6: 200 | J6: 0 | K6: PD | L6: 0.7642 | M6: 99.9047 | N6: 618.3299 | O6: 618.3299 | P6: =(O6-N6)/O6 -> 0 | Q6: 1 | R6: 1 | S6: 480 | T6: V0: [0,12,9,20,1,26] ; V1: [0,11,19,10,26] ; V2: [0,18,26] ; V3: [0,23,22,4,26] ; V4: [0,7,8,17,26] ; V5: [0,5,16,6,26] ; V6: [0,2,21,3,24,25,26] ; V7: [0,14,15,13,26] | U6: V0: [0,5,16,6,26] ; V1: [0,14,15,13,26] ; V2: [0,12,9,20,1,26] ; V3: [0,7,8,17,26] ; V4: [0,18,26] ; V5: [0,11,19,10,26] ; V6: [0,2,21,3,24,26] ; V7: [0,23,22,4,25,26] | V6: 46108.867 | W6: vns_ com acrescimo | X6: 2 | Y6: =_xlfn.MAXIFS($P:$P,$E:$E,X6) -> 0.047165122 | Z6: instancias/c202,txt | AA6: =_xlfn.MINIFS($P:$P,$E:$E,X6) -> 0 | AB6: instancias/r101,txt | AC6: =AVERAGEIFS($P:$P,$E:$E,X6) -> 0.0069774029
A7: tam25_cap200_tabu0_inst0_cons0 | B7: instancias/r102,txt | C7: 0 | D7: 0 | E7: 0 | F7: 25 | G7: 27 | H7: 7 | I7: 200 | J7: 0 | K7: PD | L7: 1201.1008 | M7: 2666.8414 | N7: 548.1078 | O7: 548.1078 | P7: =(O7-N7)/O7 -> 0 | Q7: 1 | R7: 713 | S7: 2793 | T7: V0: [0,14,16,6,13,26] ; V1: [0,3,9,20,1,26] ; V2: [0,7,11,19,10,26] ; V3: [0,2,15,22,4,25,26] ; V4: [0,18,26] ; V5: [0,8,17,5,26] ; V6: [0,21,23,24,12,26] | U7: V0: [0,14,16,6,13,26] ; V1: [0,7,11,19,10,26] ; V2: [0,21,23,24,12,26] ; V3: [0,2,15,22,4,25,26] ; V4: [0,8,17,5,26] ; V5: [0,3,9,20,1,26] ; V6: [0,18,26] | V7: 46108.912 | W7: sem pd | X7: 3 | Y7: =_xlfn.MAXIFS($P:$P,$E:$E,X7) -> 0.077869239 | Z7: instancias/c201,txt | AA7: =_xlfn.MINIFS($P:$P,$E:$E,X7) -> 0 | AB7: instancias/r101,txt | AC7: =AVERAGEIFS($P:$P,$E:$E,X7) -> 0.034711422
A8: tam25_cap200_tabu0_inst0_cons1 | B8: instancias/r102,txt | C8: 0 | D8: 0 | E8: 1 | F8: 25 | G8: 27 | H8: 7 | I8: 200 | J8: 0 | K8: PD | L8: 1201.1008 | M8: 2980.3445 | N8: 548.1078 | O8: 548.1078 | P8: =(O8-N8)/O8 -> 0 | Q8: 1 | R8: 2017 | S8: 2289 | T8: V0: [0,14,16,6,13,26] ; V1: [0,3,9,20,1,26] ; V2: [0,7,11,19,10,26] ; V3: [0,2,15,22,4,25,26] ; V4: [0,18,26] ; V5: [0,8,17,5,26] ; V6: [0,21,23,24,12,26] | U8: V0: [0,21,23,24,12,26] ; V1: [0,2,15,22,4,25,26] ; V2: [0,3,9,20,1,26] ; V3: [0,8,17,5,26] ; V4: [0,18,26] ; V5: [0,7,11,19,10,26] ; V6: [0,14,16,6,13,26] | V8: 46108.947 | W8: apenas pd | X8: 22 | Y8: =_xlfn.MAXIFS($P:$P,$E:$E,X8) -> 0.20591351 | Z8: instancias/r102,txt | AA8: =_xlfn.MINIFS($P:$P,$E:$E,X8) -> 0 | AB8: instancias/r101,txt | AC8: =AVERAGEIFS($P:$P,$E:$E,X8) -> 0.023692187
A9: tam25_cap200_tabu0_inst0_cons2 | B9: instancias/r102,txt | C9: 0 | D9: 0 | E9: 2 | F9: 25 | G9: 27 | H9: 7 | I9: 200 | J9: 0 | K9: PD | L9: 1201.1008 | M9: 2381.7852 | N9: 548.1078 | O9: 548.1078 | P9: =(O9-N9)/O9 -> 0 | Q9: 1 | R9: 1435 | S9: 2268 | T9: V0: [0,14,16,6,13,26] ; V1: [0,3,9,20,1,26] ; V2: [0,7,11,19,10,26] ; V3: [0,2,15,22,4,25,26] ; V4: [0,18,26] ; V5: [0,8,17,5,26] ; V6: [0,21,23,24,12,26] | U9: V0: [0,8,17,5,26] ; V1: [0,3,9,20,1,26] ; V2: [0,21,23,24,12,26] ; V3: [0,18,26] ; V4: [0,7,11,19,10,26] ; V5: [0,14,16,6,13,26] ; V6: [0,2,15,22,4,25,26] | V9: 46108.974 | W9: todas | X9: 10 | Y9: =_xlfn.MAXIFS($P:$P,$E:$E,X9) -> 0.032710523 | Z9: instancias/c109,txt | AA9: =_xlfn.MINIFS($P:$P,$E:$E,X9) -> 0 | AB9: instancias/r101,txt | AC9: =AVERAGEIFS($P:$P,$E:$E,X9) -> 0.0029262166
A10: tam25_cap200_tabu0_inst0_cons3 | B10: instancias/r102,txt | C10: 0 | D10: 0 | E10: 3 | F10: 25 | G10: 27 | H10: 7 | I10: 200 | J10: 0 | K10: PD | L10: 1201.1008 | M10: 106.3065 | N10: 548.1078 | O10: 551.622 | P10: =(O10-N10)/O10 -> 0.0063706669 | Q10: 0 | R10: 211 | S10: 2485 | T10: V0: [0,14,16,6,13,26] ; V1: [0,3,9,20,1,26] ; V2: [0,7,11,19,10,26] ; V3: [0,2,15,22,4,25,26] ; V4: [0,18,26] ; V5: [0,8,17,5,26] ; V6: [0,21,23,24,12,26] | U10: V0: [0,2,15,22,4,25,12,26] ; V1: [0,3,9,20,1,26] ; V2: [0,18,6,13,26] ; V3: [0,8,26] ; V4: [0,7,11,19,10,26] ; V5: [0,14,16,17,5,26] ; V6: [0,21,23,24,26] | V10: 46108.976 | W10: inserção com melhoria\grasp_bid_final com pd | X10: 33 | Y10: =_xlfn.MAXIFS($P:$P,$E:$E,X10) -> 0 | AA10: =_xlfn.MINIFS($P:$P,$E:$E,X10) -> 0 | AC10: =AVERAGEIFS($P:$P,$E:$E,X10) -> 0
A11: tam25_cap200_tabu0_inst0_cons22 | B11: instancias/r102,txt | C11: 0 | D11: 0 | E11: 22 | F11: 25 | G11: 27 | H11: 7 | I11: 200 | J11: 0 | K11: PD | L11: 1201.1008 | M11: 3600.2436 | N11: 548.1078 | O11: 690.2369 | P11: =(O11-N11)/O11 -> 0.20591351 | Q11: 0 | R11: 1878 | S11: 714 | T11: V0: [0,14,16,6,13,26] ; V1: [0,3,9,20,1,26] ; V2: [0,7,11,19,10,26] ; V3: [0,2,15,22,4,25,26] ; V4: [0,18,26] ; V5: [0,8,17,5,26] ; V6: [0,21,23,24,12,26] | U11: V0: [0,21,23,24,12,26] ; V1: [0,2,15,22,4,25,26] ; V2: [0,18,6,13,26] ; V3: [0,8,10,26] ; V4: [0,16,17,26] ; V5: [0,5,11,19,3,26] ; V6: [0,14,9,20,1,7,26] | V11: 46109.017
A12: tam25_cap200_tabu0_inst0_cons0 | B12: instancias/r103,txt | C12: 0 | D12: 0 | E12: 0 | F12: 25 | G12: 27 | H12: 5 | I12: 200 | J12: 0 | K12: PD | L12: 1201.3643 | M12: 142.071 | N12: =N14 -> 454.6 | O12: 455.6982 | P12: =(O12-N12)/O12 -> 0.0024099283 | Q12: 0 | R12: 1 | S12: 1375 | T12: V0: [0,7,19,11,10,26] ; V1: [0,2,21,23,22,4,25,26] ; V2: [0,14,15,6,13,26] ; V3: [0,1,20,9,3,24,12,26] ; V4: [0,18,8,17,16,5,26] | U12: V0: [0,7,19,11,8,18,26] ; V1: [0,12,24,3,9,10,20,1,26] ; V2: [0,2,15,14,16,17,5,26] ; V3: [0,6,13,26] ; V4: [0,21,23,22,4,25,26] | V12: 46109.033 | X12: Analise | Y12: TIME
A13: tam25_cap200_tabu0_inst0_cons1 | B13: instancias/r103,txt | C13: 0 | D13: 0 | E13: 1 | F13: 25 | G13: 27 | H13: 5 | I13: 200 | J13: 0 | K13: PD | L13: 1201.3643 | M13: 109.9558 | N13: =N14 -> 454.6 | O13: 455.6982 | P13: =(O13-N13)/O13 -> 0.0024099283 | Q13: 0 | R13: 1 | S13: 1450 | T13: V0: [0,7,19,11,10,26] ; V1: [0,2,21,23,22,4,25,26] ; V2: [0,14,15,6,13,26] ; V3: [0,1,20,9,3,24,12,26] ; V4: [0,18,8,17,16,5,26] | U13: V0: [0,2,15,14,16,17,5,26] ; V1: [0,7,19,11,8,18,26] ; V2: [0,21,23,22,4,25,26] ; V3: [0,6,13,26] ; V4: [0,12,24,3,9,10,20,1,26] | V13: 46109.034 | X13: heuristica | Y13: MÁXIMO | Z13: inst | AA13: MÍNIMO | AB13: inst | AC13: MÉDIA
A14: tam25_cap200_tabu0_inst0_cons2 | B14: instancias/r103,txt | C14: 0 | D14: 0 | E14: 2 | F14: 25 | G14: 27 | H14: 5 | I14: 200 | J14: 0 | K14: PD | L14: 1201.3643 | M14: 111.5374 | N14: =N15 -> 454.6 | O14: 455.6982 | P14: =(O14-N14)/O14 -> 0.0024099283 | Q14: 0 | R14: 1 | S14: 1380 | T14: V0: [0,7,19,11,10,26] ; V1: [0,2,21,23,22,4,25,26] ; V2: [0,14,15,6,13,26] ; V3: [0,1,20,9,3,24,12,26] ; V4: [0,18,8,17,16,5,26] | U14: V0: [0,12,24,3,9,10,20,1,26] ; V1: [0,21,23,22,4,25,26] ; V2: [0,2,15,14,16,17,5,26] ; V3: [0,6,13,26] ; V4: [0,7,19,11,8,18,26] | V14: 46109.035 | X14: 0 | Y14: =_xlfn.MAXIFS($M:$M,$E:$E,X14) -> 3999.3001 | Z14: instancias/c202,txt | AA14: =_xlfn.MINIFS($M:$M,$E:$E,X14) -> 67.9489 | AC14: =AVERAGEIFS($M:$M,$E:$E,X14) -> 1577.3656
A15: tam25_cap200_tabu0_inst0_cons3 | B15: instancias/r103,txt | C15: 0 | D15: 0 | E15: 3 | F15: 25 | G15: 27 | H15: 5 | I15: 200 | J15: 0 | K15: PD | L15: 1201.3643 | M15: 164.3832 | N15: =N16 -> 454.6 | O15: 468.1968 | P15: =(O15-N15)/O15 -> 0.029040779 | Q15: 0 | R15: 379 | S15: 2445 | T15: V0: [0,7,19,11,10,26] ; V1: [0,2,21,23,22,4,25,26] ; V2: [0,14,15,6,13,26] ; V3: [0,1,20,9,3,24,12,26] ; V4: [0,18,8,17,16,5,26] | U15: V0: [0,24,3,9,10,20,1,26] ; V1: [0,6,13,26] ; V2: [0,15,14,16,17,5,26] ; V3: [0,7,19,11,8,18,26] ; V4: [0,2,21,23,22,4,25,12,26] | V15: 46109.037 | W15: inserção com melhoria | X15: 1 | Y15: =_xlfn.MAXIFS($M:$M,$E:$E,X15) -> 3786.1477 | Z15: instancias/c203,txt | AA15: =_xlfn.MINIFS($M:$M,$E:$E,X15) -> 20.2125 | AC15: =AVERAGEIFS($M:$M,$E:$E,X15) -> 1251.4237
A16: tam25_cap200_tabu0_inst0_cons22 | B16: instancias/r103,txt | C16: 0 | D16: 0 | E16: 22 | F16: 25 | G16: 27 | H16: 5 | I16: 200 | J16: 0 | K16: PD | L16: 1201.3643 | M16: 447.5025 | N16: =N88 -> 454.6 | O16: 455.6982 | P16: =(O16-N16)/O16 -> 0.0024099283 | Q16: 0 | R16: 1 | S16: 645 | T16: V0: [0,7,19,11,10,26] ; V1: [0,2,21,23,22,4,25,26] ; V2: [0,14,15,6,13,26] ; V3: [0,1,20,9,3,24,12,26] ; V4: [0,18,8,17,16,5,26] | U16: V0: [0,21,23,22,4,25,26] ; V1: [0,2,15,14,16,17,5,26] ; V2: [0,6,13,26] ; V3: [0,7,19,11,8,18,26] ; V4: [0,12,24,3,9,10,20,1,26] | V16: 46109.042 | W16: vns_ com acrescimo | X16: 2 | Y16: =_xlfn.MAXIFS($M:$M,$E:$E,X16) -> 4212.7162 | Z16: instancias/c203,txt | AA16: =_xlfn.MINIFS($M:$M,$E:$E,X16) -> 23.3106 | AC16: =AVERAGEIFS($M:$M,$E:$E,X16) -> 1214.4434
A17: tam25_cap200_tabu0_inst0_cons0 | B17: instancias/r104,txt | C17: 0 | D17: 0 | E17: 0 | F17: 25 | G17: 27 | H17: 4 | I17: 200 | J17: 0 | K17: PD | L17: 1201.5134 | M17: 119.9116 | N17: =N18 -> 416.9 | O17: 417.9612 | P17: =(O17-N17)/O17 -> 0.0025389917 | Q17: 0 | R17: 1 | S17: 1040 | T17: V0: [0,15,16,14,13,26] ; V1: [0,21,22,23,4,2,6,26] ; V2: [0,7,19,11,8,17,5,18,26] ; V3: [0,1,10,20,9,3,24,25,12,26] | U17: V0: [0,7,19,11,8,18,6,13,26] ; V1: [0,1,10,20,9,3,24,12,26] ; V2: [0,2,15,14,16,17,5,26] ; V3: [0,21,22,23,4,25,26] | V17: 46109.058 | W17: sem pd | X17: 3 | Y17: =_xlfn.MAXIFS($M:$M,$E:$E,X17) -> 3633.8025 | Z17: instancias/c202,txt | AA17: =_xlfn.MINIFS($M:$M,$E:$E,X17) -> 2.2683 | AC17: =AVERAGEIFS($M:$M,$E:$E,X17) -> 814.73283
A18: tam25_cap200_tabu0_inst0_cons1 | B18: instancias/r104,txt | C18: 0 | D18: 0 | E18: 1 | F18: 25 | G18: 27 | H18: 4 | I18: 200 | J18: 0 | K18: PD | L18: 1201.5134 | M18: 150.0521 | N18: =N19 -> 416.9 | O18: 417.9612 | P18: =(O18-N18)/O18 -> 0.0025389917 | Q18: 0 | R18: 15 | S18: 1752 | T18: V0: [0,15,16,14,13,26] ; V1: [0,21,22,23,4,2,6,26] ; V2: [0,7,19,11,8,17,5,18,26] ; V3: [0,1,10,20,9,3,24,25,12,26] | U18: V0: [0,21,22,23,4,25,26] ; V1: [0,2,15,14,16,17,5,26] ; V2: [0,7,19,11,8,18,6,13,26] ; V3: [0,1,10,20,9,3,24,12,26] | V18: 46109.06 | W18: apenas pd | X18: 22 | Y18: =_xlfn.MAXIFS($M:$M,$E:$E,X18) -> 4555 | Z18: instancias/c203,txt | AA18: =_xlfn.MINIFS($M:$M,$E:$E,X18) -> 99.9047 | AC18: =AVERAGEIFS($M:$M,$E:$E,X18) -> 2195.5549
A19: tam25_cap200_tabu0_inst0_cons2 | B19: instancias/r104,txt | C19: 0 | D19: 0 | E19: 2 | F19: 25 | G19: 27 | H19: 4 | I19: 200 | J19: 0 | K19: PD | L19: 1201.5134 | M19: 86.7017 | N19: =N20 -> 416.9 | O19: 417.9612 | P19: =(O19-N19)/O19 -> 0.0025389917 | Q19: 0 | R19: 1 | S19: 1384 | T19: V0: [0,15,16,14,13,26] ; V1: [0,21,22,23,4,2,6,26] ; V2: [0,7,19,11,8,17,5,18,26] ; V3: [0,1,10,20,9,3,24,25,12,26] | U19: V0: [0,2,15,14,16,17,5,26] ; V1: [0,21,22,23,4,25,26] ; V2: [0,1,10,20,9,3,24,12,26] ; V3: [0,7,19,11,8,18,6,13,26] | V19: 46109.06 | W19: todas | X19: 10 | Y19: =_xlfn.MAXIFS($M:$M,$E:$E,X19) -> 3346.43 | Z19: instancias/r112,txt | AA19: =_xlfn.MINIFS($M:$M,$E:$E,X19) -> 25.3171 | AC19: =AVERAGEIFS($M:$M,$E:$E,X19) -> 545.35546
A20: tam25_cap200_tabu0_inst0_cons3 | B20: instancias/r104,txt | C20: 0 | D20: 0 | E20: 3 | F20: 25 | G20: 27 | H20: 4 | I20: 200 | J20: 0 | K20: PD | L20: 1201.5134 | M20: 18.8865 | N20: =N21 -> 416.9 | O20: 427.2213 | P20: =(O20-N20)/O20 -> 0.024159142 | Q20: 0 | R20: 1 | S20: 1744 | T20: V0: [0,15,16,14,13,26] ; V1: [0,21,22,23,4,2,6,26] ; V2: [0,7,19,11,8,17,5,18,26] ; V3: [0,1,10,20,9,3,24,25,12,26] | U20: V0: [0,1,10,20,9,3,24,25,12,26] ; V1: [0,7,19,11,8,17,16,5,18,26] ; V2: [0,21,22,23,4,26] ; V3: [0,6,14,15,2,13,26] | V20: 46109.06 | W20: inserção com melhoria\grasp_bid_final com pd | X20: 33 | Y20: =_xlfn.MAXIFS($M:$M,$E:$E,X20) -> 4210.5146 | AA20: =_xlfn.MINIFS($M:$M,$E:$E,X20) -> 16.68877 | AC20: =AVERAGEIFS($M:$M,$E:$E,X20) -> 968.74468
A21: tam25_cap200_tabu0_inst0_cons22 | B21: instancias/r104,txt | C21: 0 | D21: 0 | E21: 22 | F21: 25 | G21: 27 | H21: 4 | I21: 200 | J21: 0 | K21: PD | L21: 1201.5134 | M21: 392.8058 | N21: =N89 -> 416.9 | O21: 420.6334 | P21: =(O21-N21)/O21 -> 0.0088756623 | Q21: 0 | R21: 1 | S21: 500 | T21: V0: [0,15,16,14,13,26] ; V1: [0,21,22,23,4,2,6,26] ; V2: [0,7,19,11,8,17,5,18,26] ; V3: [0,1,10,20,9,3,24,25,12,26] | U21: V0: [0,7,19,11,8,18,6,13,26] ; V1: [0,2,15,14,16,17,5,26] ; V2: [0,21,22,23,4,25,12,26] ; V3: [0,24,3,9,20,10,1,26] | V21: 46109.065
A22: tam25_cap200_tabu0_inst0_cons0 | B22: instancias/r105,txt | C22: 0 | D22: 0 | E22: 0 | F22: 25 | G22: 27 | H22: 6 | I22: 200 | J22: 0 | K22: PD | L22: 17.8249 | M22: 90.9081 | N22: =N23 -> 530.5 | O22: 531.5386 | P22: =(O22-N22)/O22 -> 0.0019539503 | Q22: 1 | R22: 1 | S22: 828 | T22: V0: [0,5,14,16,6,26] ; V1: [0,12,9,3,24,25,26] ; V2: [0,2,15,13,26] ; V3: [0,21,23,22,4,26] ; V4: [0,7,18,8,17,26] ; V5: [0,19,11,10,20,1,26] | U22: V0: [0,5,14,16,6,26] ; V1: [0,19,11,10,20,1,26] ; V2: [0,7,18,8,17,26] ; V3: [0,12,9,3,24,26] ; V4: [0,2,15,13,26] ; V5: [0,21,23,22,4,25,26] | V22: 46109.067
A23: tam25_cap200_tabu0_inst0_cons1 | B23: instancias/r105,txt | C23: 0 | D23: 0 | E23: 1 | F23: 25 | G23: 27 | H23: 6 | I23: 200 | J23: 0 | K23: PD | L23: 17.8249 | M23: 56.1524 | N23: =N24 -> 530.5 | O23: 531.5386 | P23: =(O23-N23)/O23 -> 0.0019539503 | Q23: 1 | R23: 1 | S23: 1134 | T23: V0: [0,5,14,16,6,26] ; V1: [0,12,9,3,24,25,26] ; V2: [0,2,15,13,26] ; V3: [0,21,23,22,4,26] ; V4: [0,7,18,8,17,26] ; V5: [0,19,11,10,20,1,26] | U23: V0: [0,19,11,10,20,1,26] ; V1: [0,12,9,3,24,25,26] ; V2: [0,5,14,16,6,26] ; V3: [0,7,18,8,17,26] ; V4: [0,2,15,13,26] ; V5: [0,21,23,22,4,26] | V23: 46109.067
A24: tam25_cap200_tabu0_inst0_cons2 | B24: instancias/r105,txt | C24: 0 | D24: 0 | E24: 2 | F24: 25 | G24: 27 | H24: 6 | I24: 200 | J24: 0 | K24: PD | L24: 17.8249 | M24: 57.6008 | N24: =N25 -> 530.5 | O24: 531.5386 | P24: =(O24-N24)/O24 -> 0.0019539503 | Q24: 1 | R24: 1 | S24: 1242 | T24: V0: [0,5,14,16,6,26] ; V1: [0,12,9,3,24,25,26] ; V2: [0,2,15,13,26] ; V3: [0,21,23,22,4,26] ; V4: [0,7,18,8,17,26] ; V5: [0,19,11,10,20,1,26] | U24: V0: [0,21,23,22,4,25,26] ; V1: [0,19,11,10,20,1,26] ; V2: [0,7,18,8,17,26] ; V3: [0,5,14,16,6,26] ; V4: [0,12,9,3,24,26] ; V5: [0,2,15,13,26] | V24: 46109.068
A25: tam25_cap200_tabu0_inst0_cons3 | B25: instancias/r105,txt | C25: 0 | D25: 0 | E25: 3 | F25: 25 | G25: 27 | H25: 6 | I25: 200 | J25: 0 | K25: PD | L25: 17.8249 | M25: 22.6073 | N25: =N26 -> 530.5 | O25: 537.5166 | P25: =(O25-N25)/O25 -> 0.013053736 | Q25: 0 | R25: 65 | S25: 1452 | T25: V0: [0,5,14,16,6,26] ; V1: [0,12,9,3,24,25,26] ; V2: [0,2,15,13,26] ; V3: [0,21,23,22,4,26] ; V4: [0,7,18,8,17,26] ; V5: [0,19,11,10,20,1,26] | U25: V0: [0,18,6,26] ; V1: [0,21,23,22,4,26] ; V2: [0,12,9,3,24,25,26] ; V3: [0,5,14,16,8,17,26] ; V4: [0,11,19,7,10,20,1,26] ; V5: [0,2,15,13,26] | V25: 46109.068
A26: tam25_cap200_tabu0_inst0_cons22 | B26: instancias/r105,txt | C26: 0 | D26: 0 | E26: 22 | F26: 25 | G26: 27 | H26: 6 | I26: 200 | J26: 0 | K26: PD | L26: 17.8249 | M26: 210.8627 | N26: =N90 -> 530.5 | O26: 531.5386 | P26: =(O26-N26)/O26 -> 0.0019539503 | Q26: 1 | R26: 1 | S26: 492 | T26: V0: [0,5,14,16,6,26] ; V1: [0,12,9,3,24,25,26] ; V2: [0,2,15,13,26] ; V3: [0,21,23,22,4,26] ; V4: [0,7,18,8,17,26] ; V5: [0,19,11,10,20,1,26] | U26: V0: [0,2,15,13,26] ; V1: [0,21,23,22,4,26] ; V2: [0,12,9,3,24,25,26] ; V3: [0,19,11,10,20,1,26] ; V4: [0,7,18,8,17,26] ; V5: [0,5,14,16,6,26] | V26: 46109.07
A27: tam25_cap200_tabu0_inst0_cons0 | B27: instancias/r106,txt | C27: 0 | D27: 0 | E27: 0 | F27: 25 | G27: 27 | H27: 5 | I27: 200 | J27: 0 | K27: PD | L27: 1092.5516 | M27: 1481.3308 | N27: =N28 -> 465.4 | O27: 470.5235 | P27: =(O27-N27)/O27 -> 0.010888935 | Q27: 0 | R27: 307 | S27: 2765 | T27: V0: [0,2,15,23,22,4,25,21,26] ; V1: [0,14,16,6,13,26] ; V2: [0,7,19,11,10,26] ; V3: [0,18,8,17,5,26] ; V4: [0,1,9,20,3,24,12,26] | U27: V0: [0,1,9,20,3,24,26] ; V1: [0,14,16,6,13,26] ; V2: [0,18,8,17,5,26] ; V3: [0,2,15,23,22,21,4,25,12,26] ; V4: [0,7,19,11,10,26] | V27: 46109.1
A28: tam25_cap200_tabu0_inst0_cons1 | B28: instancias/r106,txt | C28: 0 | D28: 0 | E28: 1 | F28: 25 | G28: 27 | H28: 5 | I28: 200 | J28: 0 | K28: PD | L28: 1092.5516 | M28: 809.2501 | N28: =N29 -> 465.4 | O28: 466.4802 | P28: =(O28-N28)/O28 -> 0.0023156395 | Q28: 1 | R28: 137 | S28: 2280 | T28: V0: [0,2,15,23,22,4,25,21,26] ; V1: [0,14,16,6,13,26] ; V2: [0,7,19,11,10,26] ; V3: [0,18,8,17,5,26] ; V4: [0,1,9,20,3,24,12,26] | U28: V0: [0,7,19,11,10,26] ; V1: [0,2,15,23,22,4,25,21,26] ; V2: [0,18,8,17,5,26] ; V3: [0,14,16,6,13,26] ; V4: [0,1,9,20,3,24,12,26] | V28: 46109.11
A29: tam25_cap200_tabu0_inst0_cons2 | B29: instancias/r106,txt | C29: 0 | D29: 0 | E29: 2 | F29: 25 | G29: 27 | H29: 5 | I29: 200 | J29: 0 | K29: PD | L29: 1092.5516 | M29: 875.5637 | N29: =N30 -> 465.4 | O29: 466.4802 | P29: =(O29-N29)/O29 -> 0.0023156395 | Q29: 1 | R29: 153 | S29: 2390 | T29: V0: [0,2,15,23,22,4,25,21,26] ; V1: [0,14,16,6,13,26] ; V2: [0,7,19,11,10,26] ; V3: [0,18,8,17,5,26] ; V4: [0,1,9,20,3,24,12,26] | U29: V0: [0,7,19,11,10,26] ; V1: [0,2,15,23,22,4,25,21,26] ; V2: [0,14,16,6,13,26] ; V3: [0,1,9,20,3,24,12,26] ; V4: [0,18,8,17,5,26] | V29: 46109.119
A30: tam25_cap200_tabu0_inst0_cons3 | B30: instancias/r106,txt | C30: 0 | D30: 0 | E30: 3 | F30: 25 | G30: 27 | H30: 5 | I30: 200 | J30: 0 | K30: PD | L30: 1092.5516 | M30: 2234.3161 | N30: =N31 -> 465.4 | O30: 501.4534 | P30: =(O30-N30)/O30 -> 0.071897807 | Q30: 0 | R30: 16147 | S30: 6465 | T30: V0: [0,2,15,23,22,4,25,21,26] ; V1: [0,14,16,6,13,26] ; V2: [0,7,19,11,10,26] ; V3: [0,18,8,17,5,26] ; V4: [0,1,9,20,3,24,12,26] | U30: V0: [0,19,11,10,20,26] ; V1: [0,2,14,16,5,6,13,26] ; V2: [0,7,18,8,17,26] ; V3: [0,21,15,23,22,4,25,12,26] ; V4: [0,1,9,3,24,26] | V30: 46109.146
A31: tam25_cap200_tabu0_inst0_cons22 | B31: instancias/r106,txt | C31: 0 | D31: 0 | E31: 22 | F31: 25 | G31: 27 | H31: 5 | I31: 200 | J31: 0 | K31: PD | L31: 1092.5516 | M31: 3602.4569 | N31: =N91 -> 465.4 | O31: =O30 -> 501.4534 | P31: =(O31-N31)/O31 -> 0.071897807 | R31: 0 | S31: 0 | T31: V0: [0,2,15,23,22,4,25,21,26] ; V1: [0,14,16,6,13,26] ; V2: [0,7,19,11,10,26] ; V3: [0,18,8,17,5,26] ; V4: [0,1,9,20,3,24,12,26] | U31: SEM_SEQUENCIA_BP | V31: 46109.188
A32: tam25_cap200_tabu0_inst0_cons0 | B32: instancias/r107,txt | C32: 0 | D32: 0 | E32: 0 | F32: 25 | G32: 27 | H32: 4 | I32: 200 | J32: 0 | K32: PD | L32: 1201.3898 | M32: 169.633 | N32: =N33 -> 424.3 | O32: 425.2685 | P32: =(O32-N32)/O32 -> 0.0022773848 | Q32: 0 | R32: 1 | S32: 1156 | T32: V0: [0,6,16,14,13,26] ; V1: [0,18,7,11,19,8,17,5,26] ; V2: [0,2,15,23,22,4,25,21,26] ; V3: [0,12,24,3,9,20,10,1,26] | U32: V0: [0,18,7,11,19,8,17,16,5,26] ; V1: [0,21,23,22,4,25,24,26] ; V2: [0,12,3,9,20,10,1,26] ; V3: [0,2,15,14,6,13,26] | V32: 46109.203
A33: tam25_cap200_tabu0_inst0_cons1 | B33: instancias/r107,txt | C33: 0 | D33: 0 | E33: 1 | F33: 25 | G33: 27 | H33: 4 | I33: 200 | J33: 0 | K33: PD | L33: 1201.3898 | M33: 183.1797 | N33: =N34 -> 424.3 | O33: 425.2685 | P33: =(O33-N33)/O33 -> 0.0022773848 | Q33: 0 | R33: 1 | S33: 1808 | T33: V0: [0,6,16,14,13,26] ; V1: [0,18,7,11,19,8,17,5,26] ; V2: [0,2,15,23,22,4,25,21,26] ; V3: [0,12,24,3,9,20,10,1,26] | U33: V0: [0,12,3,9,20,10,1,26] ; V1: [0,18,7,11,19,8,17,16,5,26] ; V2: [0,21,23,22,4,25,24,26] ; V3: [0,2,15,14,6,13,26] | V33: 46109.206
A34: tam25_cap200_tabu0_inst0_cons2 | B34: instancias/r107,txt | C34: 0 | D34: 0 | E34: 2 | F34: 25 | G34: 27 | H34: 4 | I34: 200 | J34: 0 | K34: PD | L34: 1201.3898 | M34: 246.2748 | N34: =N35 -> 424.3 | O34: 425.2685 | P34: =(O34-N34)/O34 -> 0.0022773848 | Q34: 0 | R34: 1 | S34: 1976 | T34: V0: [0,6,16,14,13,26] ; V1: [0,18,7,11,19,8,17,5,26] ; V2: [0,2,15,23,22,4,25,21,26] ; V3: [0,12,24,3,9,20,10,1,26] | U34: V0: [0,18,7,11,19,8,17,16,5,26] ; V1: [0,21,23,22,4,25,24,26] ; V2: [0,12,3,9,20,10,1,26] ; V3: [0,2,15,14,6,13,26] | V34: 46109.208
A35: tam25_cap200_tabu0_inst0_cons3 | B35: instancias/r107,txt | C35: 0 | D35: 0 | E35: 3 | F35: 25 | G35: 27 | H35: 4 | I35: 200 | J35: 0 | K35: PD | L35: 1201.3898 | M35: 115.3156 | N35: =N36 -> 424.3 | O35: 431.1264 | P35: =(O35-N35)/O35 -> 0.015833871 | Q35: 0 | R35: 193 | S35: 2296 | T35: V0: [0,6,16,14,13,26] ; V1: [0,18,7,11,19,8,17,5,26] ; V2: [0,2,15,23,22,4,25,21,26] ; V3: [0,12,24,3,9,20,10,1,26] | U35: V0: [0,23,22,21,4,25,24,26] ; V1: [0,18,7,11,19,8,17,16,5,26] ; V2: [0,12,3,9,20,10,1,26] ; V3: [0,2,15,14,6,13,26] | V35: 46109.21
A36: tam25_cap200_tabu0_inst0_cons22 | B36: instancias/r107,txt | C36: 0 | D36: 0 | E36: 22 | F36: 25 | G36: 27 | H36: 4 | I36: 200 | J36: 0 | K36: PD | L36: 1201.3898 | M36: 443.1022 | N36: =N92 -> 424.3 | O36: 425.2685 | P36: =(O36-N36)/O36 -> 0.0022773848 | Q36: 0 | R36: 1 | S36: 472 | T36: V0: [0,6,16,14,13,26] ; V1: [0,18,7,11,19,8,17,5,26] ; V2: [0,2,15,23,22,4,25,21,26] ; V3: [0,12,24,3,9,20,10,1,26] | U36: V0: [0,21,23,22,4,25,24,26] ; V1: [0,2,15,14,6,13,26] ; V2: [0,12,3,9,20,10,1,26] ; V3: [0,18,7,11,19,8,17,16,5,26] | V36: 46109.215
A37: tam25_cap200_tabu0_inst0_cons0 | B37: instancias/r108,txt | C37: 0 | D37: 0 | E37: 0 | F37: 25 | G37: 27 | H37: 4 | I37: 200 | J37: 0 | K37: PD | L37: 1201.4456 | M37: 3618.3219 | N37: =N38 -> 397.3 | O37: 418.3557 | P37: =(O37-N37)/O37 -> 0.05032966 | Q37: 0 | R37: 212 | S37: 5284 | T37: V0: [0,21,22,23,4,25,24,26] ; V1: [0,7,10,11,19,8,18,26] ; V2: [0,12,3,9,20,1,26] ; V3: [0,2,15,14,16,17,5,6,13,26] | U37: V0: [0,12,24,3,9,20,1,26] ; V1: [0,10,19,11,7,8,18,26] ; V2: [0,2,15,23,22,4,25,21,26] ; V3: [0,6,5,17,16,14,13,26] | V37: 46109.27
A38: tam25_cap200_tabu0_inst0_cons1 | B38: instancias/r108,txt | C38: 0 | D38: 0 | E38: 1 | F38: 25 | G38: 27 | H38: 4 | I38: 200 | J38: 0 | K38: PD | L38: 1201.4456 | M38: 426.5231 | N38: =N39 -> 397.3 | O38: 398.2947 | P38: =(O38-N38)/O38 -> 0.002497397 | Q38: 1 | R38: 9 | S38: 2032 | T38: V0: [0,21,22,23,4,25,24,26] ; V1: [0,7,10,11,19,8,18,26] ; V2: [0,12,3,9,20,1,26] ; V3: [0,2,15,14,16,17,5,6,13,26] | U38: V0: [0,2,15,14,16,17,5,6,13,26] ; V1: [0,7,10,11,19,8,18,26] ; V2: [0,1,20,9,3,12,26] ; V3: [0,21,22,23,4,25,24,26] | V38: 46109.275
A39: tam25_cap200_tabu0_inst0_cons2 | B39: instancias/r108,txt | C39: 0 | D39: 0 | E39: 2 | F39: 25 | G39: 27 | H39: 4 | I39: 200 | J39: 0 | K39: PD | L39: 1201.4456 | M39: 1033.4836 | N39: =N40 -> 397.3 | O39: 398.2947 | P39: =(O39-N39)/O39 -> 0.002497397 | Q39: 1 | R39: 95 | S39: 2328 | T39: V0: [0,21,22,23,4,25,24,26] ; V1: [0,7,10,11,19,8,18,26] ; V2: [0,12,3,9,20,1,26] ; V3: [0,2,15,14,16,17,5,6,13,26] | U39: V0: [0,7,10,11,19,8,18,26] ; V1: [0,2,15,14,16,17,5,6,13,26] ; V2: [0,1,20,9,3,12,26] ; V3: [0,21,22,23,4,25,24,26] | V39: 46109.287
A40: tam25_cap200_tabu0_inst0_cons3 | B40: instancias/r108,txt | C40: 0 | D40: 0 | E40: 3 | F40: 25 | G40: 27 | H40: 4 | I40: 200 | J40: 0 | K40: PD | L40: 1201.4456 | M40: 170.8266 | N40: =N41 -> 397.3 | O40: 412.6813 | P40: =(O40-N40)/O40 -> 0.037271619 | Q40: 0 | R40: 227 | S40: 2972 | T40: V0: [0,21,22,23,4,25,24,26] ; V1: [0,7,10,11,19,8,18,26] ; V2: [0,12,3,9,20,1,26] ; V3: [0,2,15,14,16,17,5,6,13,26] | U40: V0: [0,14,15,2,13,26] ; V1: [0,21,22,23,4,25,24,26] ; V2: [0,12,3,9,20,10,1,26] ; V3: [0,18,7,11,19,8,17,16,5,6,26] | V40: 46109.29
...

Sheet SM25
A1: run_id | B1: instancia | C1: modo | D1: gamma_ini | E1: gamma_max | F1: sem_melhora | G1: melhor_LB | H1: melhor_UB | I1: gap_final_% | J1: iteracoes | K1: n_colunas_final | M1: Tempos
A2: c101N_g10_G50_SM10 | B2: c101N | C2: SEM_estab | D2: 10 | E2: 50 | F2: 10 | G2: 191.3 | H2: 191.3 | I2: =IFERROR((H2-VLOOKUP(B2,FO_CONHECIDA!$A:$B,2,FALSE))/VLOOKUP(B2,FO_CONHECIDA!$A:$B,2,FALSE),0) -> 0 | J2: 221 | K2: 412 | M2: 78.450451 | R2: Analise final
A3: c101N_g10_G50_SM15 | B3: c101N | C3: SEM_estab | D3: 10 | E3: 50 | F3: 15 | G3: 191.3 | H3: 191.3 | I3: =IFERROR((H3-VLOOKUP(B3,FO_CONHECIDA!$A:$B,2,FALSE))/VLOOKUP(B3,FO_CONHECIDA!$A:$B,2,FALSE),0) -> 0 | J3: 226 | K3: 422 | M3: 87.789192 | R3: Sem Melhora | S3: Gap Médio | T3: Gap Min | U3: Gap Max | V3: Tempo Médio | W3: Ncolunas | X3: Iteracoes
A4: c101N_g10_G50_SM20 | B4: c101N | C4: SEM_estab | D4: 10 | E4: 50 | F4: 20 | G4: 191.3 | H4: 191.3 | I4: =IFERROR((H4-VLOOKUP(B4,FO_CONHECIDA!$A:$B,2,FALSE))/VLOOKUP(B4,FO_CONHECIDA!$A:$B,2,FALSE),0) -> 0 | J4: 231 | K4: 434 | M4: 100.12157 | R4: 10 | S4: =AVERAGEIFS($I:$I,$F:$F,R4) -> 0.097499333 | T4: =_xlfn.MINIFS($I:$I,$F:$F,R4) -> 0 | U4: =_xlfn.MAXIFS($I:$I,$F:$F,R4) -> 0.70310037 | V4: =AVERAGEIFS($M:$M,$F:$F,R4) -> 151.011 | W4: =AVERAGEIFS($K:$K,$F:$F,R4) -> 620.6 | X4: =AVERAGEIFS($J:$J,$F:$F,R4) -> 220.73333
A5: c101N_g10_G50_SM25 | B5: c101N | C5: SEM_estab | D5: 10 | E5: 50 | F5: 25 | G5: 191.3 | H5: 191.3 | I5: =IFERROR((H5-VLOOKUP(B5,FO_CONHECIDA!$A:$B,2,FALSE))/VLOOKUP(B5,FO_CONHECIDA!$A:$B,2,FALSE),0) -> 0 | J5: 236 | K5: 443 | M5: 113.68224 | R5: 15 | S5: =AVERAGEIFS($I:$I,$F:$F,R5) -> 0.052303547 | T5: =_xlfn.MINIFS($I:$I,$F:$F,R5) -> -2.5008103e-16 | U5: =_xlfn.MAXIFS($I:$I,$F:$F,R5) -> 0.39362258 | V5: =AVERAGEIFS($M:$M,$F:$F,R5) -> 169.69999 | W5: =AVERAGEIFS($K:$K,$F:$F,R5) -> 641.13333 | X5: =AVERAGEIFS($J:$J,$F:$F,R5) -> 232.73333
A6: c101N_g10_G50_SM30 | B6: c101N | C6: SEM_estab | D6: 10 | E6: 50 | F6: 30 | G6: 191.3 | H6: 191.3 | I6: =IFERROR((H6-VLOOKUP(B6,FO_CONHECIDA!$A:$B,2,FALSE))/VLOOKUP(B6,FO_CONHECIDA!$A:$B,2,FALSE),0) -> 0 | J6: 241 | K6: 449 | M6: 129.557 | R6: 20 | S6: =AVERAGEIFS($I:$I,$F:$F,R6) -> 0.0075163684 | T6: =_xlfn.MINIFS($I:$I,$F:$F,R6) -> -2.5008103e-16 | U6: =_xlfn.MAXIFS($I:$I,$F:$F,R6) -> 0.058855003 | V6: =AVERAGEIFS($M:$M,$F:$F,R6) -> 269.95351 | W6: =AVERAGEIFS($K:$K,$F:$F,R6) -> 675.53333 | X6: =AVERAGEIFS($J:$J,$F:$F,R6) -> 250.26667
A7: c101N_g10_G50_SM40 | B7: c101N | C7: SEM_estab | D7: 10 | E7: 50 | F7: 40 | G7: 191.3 | H7: 191.3 | I7: =IFERROR((H7-VLOOKUP(B7,FO_CONHECIDA!$A:$B,2,FALSE))/VLOOKUP(B7,FO_CONHECIDA!$A:$B,2,FALSE),0) -> 0 | J7: 242 | K7: 451 | M7: 133.66419 | R7: 25 | S7: =AVERAGEIFS($I:$I,$F:$F,R7) -> 0.0053233149 | T7: =_xlfn.MINIFS($I:$I,$F:$F,R7) -> -2.5008103e-16 | U7: =_xlfn.MAXIFS($I:$I,$F:$F,R7) -> 0.058855003 | V7: =AVERAGEIFS($M:$M,$F:$F,R7) -> 287.06637 | W7: =AVERAGEIFS($K:$K,$F:$F,R7) -> 685.26667 | X7: =AVERAGEIFS($J:$J,$F:$F,R7) -> 254.73333
A8: c101N_g10_G50_SM50 | B8: c101N | C8: SEM_estab | D8: 10 | E8: 50 | F8: 50 | G8: 191.3 | H8: 191.3 | I8: =IFERROR((H8-VLOOKUP(B8,FO_CONHECIDA!$A:$B,2,FALSE))/VLOOKUP(B8,FO_CONHECIDA!$A:$B,2,FALSE),0) -> 0 | J8: 242 | K8: 451 | M8: 134.17439 | R8: 30 | S8: =AVERAGEIFS($I:$I,$F:$F,R8) -> 0.001399648 | T8: =_xlfn.MINIFS($I:$I,$F:$F,R8) -> -2.5008103e-16 | U8: =_xlfn.MAXIFS($I:$I,$F:$F,R8) -> 0.016290068 | V8: =AVERAGEIFS($M:$M,$F:$F,R8) -> 306.44551 | W8: =AVERAGEIFS($K:$K,$F:$F,R8) -> 693.2 | X8: =AVERAGEIFS($J:$J,$F:$F,R8) -> 260.8
A9: c102_g10_G50_SM10 | B9: c102 | C9: SEM_estab | D9: 10 | E9: 50 | F9: 10 | G9: 378.57946 | H9: 324.1 | I9: =IFERROR((H9-VLOOKUP(B9,FO_CONHECIDA!$A:$B,2,FALSE))/VLOOKUP(B9,FO_CONHECIDA!$A:$B,2,FALSE),0) -> 0.70310037 | J9: 495 | K9: 1100 | M9: 110 | R9: 40 | S9: =AVERAGEIFS($I:$I,$F:$F,R9) -> 0.00031364349 | T9: =_xlfn.MINIFS($I:$I,$F:$F,R9) -> -2.5008103e-16 | U9: =_xlfn.MAXIFS($I:$I,$F:$F,R9) -> 0.0047046524 | V9: =AVERAGEIFS($M:$M,$F:$F,R9) -> 314.36897 | W9: =AVERAGEIFS($K:$K,$F:$F,R9) -> 697.46667 | X9: =AVERAGEIFS($J:$J,$F:$F,R9) -> 263.4
A10: c102_g10_G50_SM15 | B10: c102 | C10: SEM_estab | D10: 10 | E10: 50 | F10: 15 | G10: 212.8 | H10: 212.8 | I10: =IFERROR((H10-VLOOKUP(B10,FO_CONHECIDA!$A:$B,2,FALSE))/VLOOKUP(B10,FO_CONHECIDA!$A:$B,2,FALSE),0) -> 0.11823437 | J10: 511 | K10: 1149 | M10: 120 | R10: 50 | S10: =AVERAGEIFS($I:$I,$F:$F,R10) -> 0.00031364349 | T10: =_xlfn.MINIFS($I:$I,$F:$F,R10) -> -2.5008103e-16 | U10: =_xlfn.MAXIFS($I:$I,$F:$F,R10) -> 0.0047046524 | V10: =AVERAGEIFS($M:$M,$F:$F,R10) -> 322.92019 | W10: =AVERAGEIFS($K:$K,$F:$F,R10) -> 701.8 | X10: =AVERAGEIFS($J:$J,$F:$F,R10) -> 265.4
A11: c102_g10_G50_SM20 | B11: c102 | C11: SEM_estab | D11: 10 | E11: 50 | F11: 20 | G11: 190.3 | H11: 190.3 | I11: =IFERROR((H11-VLOOKUP(B11,FO_CONHECIDA!$A:$B,2,FALSE))/VLOOKUP(B11,FO_CONHECIDA!$A:$B,2,FALSE),0) -> 0 | J11: 535 | K11: 1156 | M11: 134.61288
A12: c102_g10_G50_SM25 | B12: c102 | C12: SEM_estab | D12: 10 | E12: 50 | F12: 25 | G12: 190.3 | H12: 190.3 | I12: =IFERROR((H12-VLOOKUP(B12,FO_CONHECIDA!$A:$B,2,FALSE))/VLOOKUP(B12,FO_CONHECIDA!$A:$B,2,FALSE),0) -> 0 | J12: 540 | K12: 1168 | M12: 159.25977
A13: c102_g10_G50_SM30 | B13: c102 | C13: SEM_estab | D13: 10 | E13: 50 | F13: 30 | G13: 190.3 | H13: 190.3 | I13: =IFERROR((H13-VLOOKUP(B13,FO_CONHECIDA!$A:$B,2,FALSE))/VLOOKUP(B13,FO_CONHECIDA!$A:$B,2,FALSE),0) -> 0 | J13: 545 | K13: 1178 | M13: 175.63055
A14: c102_g10_G50_SM40 | B14: c102 | C14: SEM_estab | D14: 10 | E14: 50 | F14: 40 | G14: 190.3 | H14: 190.3 | I14: =IFERROR((H14-VLOOKUP(B14,FO_CONHECIDA!$A:$B,2,FALSE))/VLOOKUP(B14,FO_CONHECIDA!$A:$B,2,FALSE),0) -> 0 | J14: 555 | K14: 1196 | M14: 189.60085
A15: c102_g10_G50_SM50 | B15: c102 | C15: SEM_estab | D15: 10 | E15: 50 | F15: 50 | G15: 190.3 | H15: 190.3 | I15: =IFERROR((H15-VLOOKUP(B15,FO_CONHECIDA!$A:$B,2,FALSE))/VLOOKUP(B15,FO_CONHECIDA!$A:$B,2,FALSE),0) -> 0 | J15: 565 | K15: 1217 | M15: 204.25342
A16: c103_g10_G50_SM10 | B16: c103 | C16: SEM_estab | D16: 10 | E16: 50 | F16: 10 | G16: 193.4 | H16: 193.4 | I16: =IFERROR((H16-VLOOKUP(B16,FO_CONHECIDA!$A:$B,2,FALSE))/VLOOKUP(B16,FO_CONHECIDA!$A:$B,2,FALSE),0) -> 0.016290068 | J16: 397 | K16: 869 | M16: 145.45041
A17: c103_g10_G50_SM15 | B17: c103 | C17: SEM_estab | D17: 10 | E17: 50 | F17: 15 | G17: 193.4 | H17: 193.4 | I17: =IFERROR((H17-VLOOKUP(B17,FO_CONHECIDA!$A:$B,2,FALSE))/VLOOKUP(B17,FO_CONHECIDA!$A:$B,2,FALSE),0) -> 0.016290068 | J17: 402 | K17: 875 | M17: 159.48631
A18: c103_g10_G50_SM20 | B18: c103 | C18: SEM_estab | D18: 10 | E18: 50 | F18: 20 | G18: 193.4 | H18: 193.4 | I18: =IFERROR((H18-VLOOKUP(B18,FO_CONHECIDA!$A:$B,2,FALSE))/VLOOKUP(B18,FO_CONHECIDA!$A:$B,2,FALSE),0) -> 0.016290068 | J18: 407 | K18: 887 | M18: 188.88957
A19: c103_g10_G50_SM25 | B19: c103 | C19: SEM_estab | D19: 10 | E19: 50 | F19: 25 | G19: 193.4 | H19: 193.4 | I19: =IFERROR((H19-VLOOKUP(B19,FO_CONHECIDA!$A:$B,2,FALSE))/VLOOKUP(B19,FO_CONHECIDA!$A:$B,2,FALSE),0) -> 0.016290068 | J19: 412 | K19: 898 | M19: 222.88654
A20: c103_g10_G50_SM30 | B20: c103 | C20: SEM_estab | D20: 10 | E20: 50 | F20: 30 | G20: 193.4 | H20: 193.4 | I20: =IFERROR((H20-VLOOKUP(B20,FO_CONHECIDA!$A:$B,2,FALSE))/VLOOKUP(B20,FO_CONHECIDA!$A:$B,2,FALSE),0) -> 0.016290068 | J20: 417 | K20: 908 | M20: 239.69586
A21: c103_g10_G50_SM40 | B21: c103 | C21: SEM_estab | D21: 10 | E21: 50 | F21: 40 | G21: 190.3 | H21: 190.3 | I21: =IFERROR((H21-VLOOKUP(B21,FO_CONHECIDA!$A:$B,2,FALSE))/VLOOKUP(B21,FO_CONHECIDA!$A:$B,2,FALSE),0) -> 0 | J21: 425 | K21: 922 | M21: 241.20951
A22: c103_g10_G50_SM50 | B22: c103 | C22: SEM_estab | D22: 10 | E22: 50 | F22: 50 | G22: 190.3 | H22: 190.3 | I22: =IFERROR((H22-VLOOKUP(B22,FO_CONHECIDA!$A:$B,2,FALSE))/VLOOKUP(B22,FO_CONHECIDA!$A:$B,2,FALSE),0) -> 0 | J22: 425 | K22: 922 | M22: 231.82367
... A106: r106_g30_G50_SM40 | B106: r106 | C106: SEM_estab | D106: 30 | E106: 50 | F106: 50 | G106: 468.3 | H106: 465.4 | I106: =IFERROR((H106-VLOOKUP(B106,FO_CONHECIDA!$A:$B,2,FALSE))/VLOOKUP(B106,FO_CONHECIDA!$A:$B,2,FALSE),0) -> 0 | J106: 216 | K106: 878 | M106: 1808.5136

Sheet Análise_25nósComSemEstabIntegGe
B1: Branch-and-Price VRPTW — Análise Comparativa · 25 Nós · Solomon
B2: 4 cenários: Estabilização (COM/SEM) × Construtiva (Geométrica/Inteligente) · Configuração escolhida: COM Estab + Inteligente
B4: RESUMO GERAL — 29 Instâncias
B5: Cenário | C5: Ótimos | D5: % Ótimos | E5: Iter. Méd. | F5: Colunas Méd. | G5: |Gap| Méd. | I5: Vence em | J5: Iter. vs melhor | K5: Cols. vs melhor | L5: Decisão
B6: COM Estab + Geo | C6: 26/29 | D6: 0.89655172 | E6: 97.137931 | F6: 356.31034 | G6: 0.00026496552 | J6: -0.21422594 | K6: 0.047652844
B7: COM Estab + Int | C7: 29/29 | D7: 1 | E7: 123.62069 | F7: 340.10345 | G7: 0 | I7: ★ MELHOR | J7: — | K7: — | L7: ESCOLHIDO ✓
B8: SEM Estab + Geo | C8: 25/29 | D8: 0.86206897 | E8: 157.24138 | F8: 533.68966 | G8: 0.0036773571 | J8: 0.27196653 | K8: 0.56919801
B9: SEM Estab + Int | C9: 29/29 | D9: 1 | E9: 187.37931 | F9: 535.86207 | G9: 4.2243134e-05 | J9: 0.51576011 | K9: 0.57558552
B11: CRITÉRIO DE ESCOLHA
B12: Critério | C12: Justificativa
B13: 1. Qualidade (100% ótimos) | C13: Apenas COM_Int e SEM_Int atingem 29/29 ótimos. COM_Geo fica em 26/29 — instâncias r110, r111 e rc101 permanecem abertas.
B14: 2. Pool de colunas (efic.) | C14: COM_Int tem o menor pool com estabilização (340 colunas), 4,5% abaixo do COM_Geo (356). Pools menores são críticos ao escalar para 50/100 nós.
B15: 3. Estabilização (robustez) | C15: A estabilização reduz 34–39% de iterações e 33–37% de colunas em média. SEM_Int também é ótimo, mas usa 57% mais iterações e 57% mais colunas que COM_Int.
B16: 4. Escabilidade | C16: Menor pool por iteração significa menor custo computacional acumulado em instâncias maiores, onde timeout é o principal risco.
B18: MÉDIAS POR FAMÍLIA
B19: Família | C19: Métrica | D19: COM Estab + Geo | E19: COM Estab + Int | F19: SEM Estab + Geo | G19: SEM Estab + Int | H19: Melhor
B20: C (9) | C20: Ótimos (%) | D20: 1 | E20: 1 | F20: 0.88888889 | G20: 1 | H20: COM_Geo
C21: Iterações | D21: 134.22222 | E21: 160.77778 | F21: 196.66667 | G21: 305 | H21: COM_Geo
C22: Colunas | D22: 327.55556 | E22: 324.88889 | F22: 509.22222 | G22: 640.11111 | H22: COM_Int
B24: R (12) | C24: Ótimos (%) | D24: 0.83333333 | E24: 1 | F24: 0.83333333 | G24: 1 | H24: COM_Int
C25: Iterações | D25: 111.33333 | E25: 156.41667 | F25: 177.16667 | G25: 191.08333 | H25: COM_Geo
C26: Colunas | D26: 499.5 | E26: 517.16667 | F26: 717.58333 | G26: 719.58333 | H26: COM_Geo
B28: RC (8) | C28: Ótimos (%) | D28: 0.875 | E28: 1 | F28: 0.875 | G28: 1 | H28: COM_Int
C29: Iterações | D29: 34.125 | E29: 32.625 | F29: 83 | G29: 49.5 | H29: COM_Int
C30: Colunas | D30: 173.875 | E30: 91.625 | F30: 285.375 | G30: 143 | H30: COM_Int
B32: GERAL (29) | C32: Ótimos (%) | D32: 0.89655172 | E32: 1 | F32: 0.86206897 | G32: 1 | H32: COM_Int
C33: Iterações | D33: 97.137931 | E33: 123.62069 | F33: 157.24138 | G33: 187.37931 | H33: COM_Geo
C34: Colunas | D34: 356.31034 | E34: 340.10345 | F34: 533.68966 | G34: 535.86207 | H34: COM_Int
B37: IMPACTO DA ESTABILIZAÇÃO — Redução COM vs SEM (%)
B38: Família | C38: Métrica | D38: COM_Geo | E38: SEM_Geo | F38: Redução (Geo) | G38: COM_Int | H38: SEM_Int | I38: Redução (Int)
B39: C (9) | C39: Iterações | D39: 134.22222 | E39: 196.66667 | F39: 0.31751412 | G39: 160.77778 | H39: 305 | I39: 0.47285974
C40: Colunas | D40: 327.55556 | E40: 509.22222 | F40: 0.35675322 | G40: 324.88889 | H40: 640.11111 | I40: 0.49244923
B42: R (12) | C42: Iterações | D42: 111.33333 | E42: 177.16667 | F42: 0.37158984 | G42: 156.41667 | H42: 191.08333 | I42: 0.18142172
C43: Colunas | D43: 499.5 | E43: 717.58333 | F43: 0.3039136 | G43: 517.16667 | H43: 719.58333 | I43: 0.28129705
B45: RC (8) | C45: Iterações | D45: 34.125 | E45: 83 | F45: 0.58885542 | G45: 32.625 | H45: 49.5 | I45: 0.34090909
C46: Colunas | D46: 173.875 | E46: 285.375 | F46: 0.39071397 | G46: 91.625 | H46: 143 | I46: 0.35926573
B48: GERAL (29) | C48: Iterações | D48: 97.137931 | E48: 157.24138 | F48: 0.38223684 | G48: 123.62069 | H48: 187.37931 | I48: 0.340265
C49: Colunas | D49: 356.31034 | E49: 533.68966 | F49: 0.33236415 | G49: 340.10345 | H49: 535.86207 | I49: 0.36531532
B52: GRÁFICO 1 — % Ótimos por Família e Cenário
B53: Família | C53: COM Estab + Geo | D53: COM Estab + Int | E53: SEM Estab + Geo | F53: SEM Estab + Int
...

Sheet FO_CONHECIDA
A1: nos | B1: 25 | D1: nos | E1: 50
A2: instancia | B2: FO | D2: Instancia | E2: Familia | F2: UB_lit | G2: LB_lit | J2: Construtiva 50
A3: c101N | B3: 191.3 | D3: C101N | E3: C | F3: 362.4 | G3: 362.4 | J3: 362.4
A4: c102 | B4: 190.3 | D4: C102 | E4: C | F4: 362.4 | G4: 362.4 | J4: 376.4
A5: c103 | B5: 190.3 | D5: C103 | E5: C | F5: 361.4 | G5: 361.4 | J5: 410.4
A6: c104 | B6: 186.9 | D6: C104 | E6: C | F6: 362.4 | G6: 362.4 | J6: 402.1
A7: c105 | B7: 191.3 | D7: C105 | E7: C | F7: 362.4 | G7: 362.4 | J7: 373.5
A8: c106 | B8: 191.3 | D8: C106 | E8: C | F8: 1044 | G8: 1043.3 | J8: 365.4
A9: c107 | B9: 191.3 | D9: C107 | E9: C | F9: 909 | G9: 909 | J9: 365.2
A10: c108 | B10: 191.3 | D10: C108 | E10: C | F10: 772.9 | G10: 769.2 | J10: 431.3
A11: c109 | B11: 191.3 | D11: C109 | E11: C | F11: 629.4 | G11: 619.1 | J11: 391.1
A12: r101 | B12: 617.1 | D12: R101 | E12: R | F12: 903.7 | G12: 892.1 | J12: 1139.3
A13: r102 | B13: 547.1 | D13: R102 | E13: R | F13: 793 | G13: 791.3 | J13: 946.5
A14: r103 | B14: 454.6 | D14: R103 | E14: R | F14: 711.1 | G14: 707.2 | J14: 911.3
... A31: RC108-25 | B31: 294.5 | D31: RC108 | E31: RC | F31: 1081.1 | G31: 1001.2 | J31: 654.1

Sheet Construtiva50
A1: c101n | B1: | | C1: custo= | D1: 362.4 | E1: | | F1: 0 | G1: art | H1: ✓
A2: c102 | B2: | | C2: custo= | D2: 376.4 | E2: | | F2: 0 | G2: art | H2: ✓
A3: c103 | B3: | | C3: custo= | D3: 410.4 | E3: | | F3: 0 | G3: art | H3: ✓
A4: c104 | B4: | | C4: custo= | D4: 402.1 | E4: | | F4: 0 | G4: art | H4: ✓
A5: c105 | B5: | | C5: custo= | D5: 373.5 | E5: | | F5: 0 | G5: art | H5: ✓
A6: c106 | B6: | | C6: custo= | D6: 365.4 | E6: | | F6: 0 | G6: art | H6: ✓
A7: c107 | B7: | | C7: custo= | D7: 365.2 | E7: | | F7: 0 | G7: art | H7: ✓
A8: c108 | B8: | | C8: custo= | D8: 431.3 | E8: | | F8: 0 | G8: art | H8: ✓
A9: c109 | B9: | | C9: custo= | D9: 391.1 | E9: | | F9: 0 | G9: art | H9: ✓
A10: r101 | B10: | | C10: custo= | D10: 1139.3 | E10: | | F10: 0 | G10: art | H10: ✓
A11: r102 | B11: | | C11: custo= | D11: 946.5 | E11: | | F11: 0 | G11: art | H11: ✓
A12: r103 | B12: | | C12: custo= | D12: 911.3 | E12: | | F12: 0 | G12: art | H12: ✓
... A29: rc108 | B29: | | C29: custo= | D29: 654.1 | E29: | | F29: 0 | G29: art | H29: ✓
